<sdf version='1.5'>
  <world name='default'>
    <gui fullscreen='0'>
      <camera name='user_camera'>
        <pose frame=''>1.82395 -7.34645 1.03976 0 -0 1.571</pose>
        <view_controller>orbit</view_controller>
      </camera>
    </gui>
    <physics name='default_physics' default='0' type='ode'>
      <gravity>0 0 -9.81</gravity>
      <simbody>
        <accuracy>0.005</accuracy>
        <max_transient_velocity>0.005</max_transient_velocity>
        <contact>
          <stiffness>1e+08</stiffness>
          <dissipation>20</dissipation>
        </contact>
      </simbody>
      <ode>
        <solver>
          <use_dynamic_moi_rescaling>1</use_dynamic_moi_rescaling>
          <type>quick</type>
          <iters>200</iters>
          <sor>1</sor>
        </solver>
        <constraints>
          <cfm>0</cfm>
          <erp>0.2</erp>
          <contact_max_correcting_vel>100</contact_max_correcting_vel>
          <contact_surface_layer>0</contact_surface_layer>
        </constraints>
      </ode>
      <real_time_update_rate>1000</real_time_update_rate>
      <max_step_size>0.001</max_step_size>
      <real_time_factor>1</real_time_factor>
      <magnetic_field>5.5645e-06 2.28758e-05 -4.23884e-05</magnetic_field>
    </physics>
    <light name='sun' type='directional'>
      <cast_shadows>1</cast_shadows>
      <pose frame=''>0 0 10 0 -0 0</pose>
      <diffuse>0.8 0.8 0.8 1</diffuse>
      <specular>0.2 0.2 0.2 1</specular>
      <attenuation>
        <range>1000</range>
        <constant>0.9</constant>
        <linear>0.01</linear>
        <quadratic>0.001</quadratic>
      </attenuation>
      <direction>-0.5 0.1 -0.9</direction>
    </light>
    <model name='ground_plane'>
      <static>1</static>
      <link name='link'>
        <collision name='collision'>
          <geometry>
            <plane>
              <normal>0 0 1</normal>
              <size>100 100</size>
            </plane>
          </geometry>
          <surface>
            <friction>
              <ode>
                <mu>100</mu>
                <mu2>50</mu2>
              </ode>
            </friction>
            <contact>
              <ode/>
            </contact>
            <bounce/>
          </surface>
          <max_contacts>10</max_contacts>
        </collision>
        <visual name='visual'>
          <cast_shadows>0</cast_shadows>
          <geometry>
            <plane>
              <normal>0 0 1</normal>
              <size>100 100</size>
            </plane>
          </geometry>
          <material>
            <script>
              <uri>file://media/materials/scripts/gazebo.material</uri>
              <name>Gazebo/Grey</name>
            </script>
          </material>
        </visual>
        <self_collide>0</self_collide>
        <kinematic>0</kinematic>
        <gravity>1</gravity>
      </link>
    </model>
    <plugin name='vrc_plugin' filename='libVRCPlugin.so'>
      <atlas>
        <model_name>atlas</model_name>
        <pin_link>utorso</pin_link>
      </atlas>
      <drc_vehicle>
        <model_name>golf_cart</model_name>
        <seat_link>chassis</seat_link>
      </drc_vehicle>
      <drc_fire_hose>
        <fire_hose_model>fire_hose</fire_hose_model>
        <coupling_link>coupling</coupling_link>
        <standpipe_model>standpipe</standpipe_model>
        <spout_link>standpipe</spout_link>
        <thread_pitch>-1000</thread_pitch>
        <coupling_relative_pose>1.17038e-05 -0.125623 0.35 -0.0412152 -1.57078 1.61199</coupling_relative_pose>
      </drc_fire_hose>
    </plugin>
    <plugin name='vrc_scoring' filename='libVRCScoringPlugin.so'/>
    <scene>
      <ambient>0.4 0.4 0.4 1</ambient>
      <background>0.7 0.7 0.7 1</background>
      <shadows>1</shadows>
    </scene>
    <spherical_coordinates>
      <surface_model>EARTH_WGS84</surface_model>
      <latitude_deg>0</latitude_deg>
      <longitude_deg>0</longitude_deg>
      <elevation>0</elevation>
      <heading_deg>0</heading_deg>
    </spherical_coordinates>
    <model name='atlas'>
      <link name='pelvis'>
        <pose frame=''>0 0 0 0 -0 0</pose>
        <inertial>
          <pose frame=''>0.011608 0 0.0266707 0 -0 0</pose>
          <mass>9.609</mass>
          <inertia>
            <ixx>0.125568</ixx>
            <ixy>0.0008</ixy>
            <ixz>-0.000500733</ixz>
            <iyy>0.0972042</iyy>
            <iyz>-0.0005</iyz>
            <izz>0.117936</izz>
          </inertia>
        </inertial>
        <collision name='pelvis_collision'>
          <pose frame=''>0.046 0 0.01 1.5708 -0 0</pose>
          <geometry>
            <cylinder>
              <length>0.06</length>
              <radius>0.11</radius>
            </cylinder>
          </geometry>
          <surface>
            <contact>
              <ode/>
            </contact>
            <friction>
              <ode>
                <mu>0.9</mu>
                <mu2>0.9</mu2>
              </ode>
            </friction>
            <bounce/>
          </surface>
          <max_contacts>10</max_contacts>
        </collision>
        <collision name='pelvis_collision_pelvis_1'>
          <pose frame=''>-0.03 0 0.01 1.5708 -0 0</pose>
          <geometry>
            <cylinder>
              <length>0.06</length>
              <radius>0.11</radius>
            </cylinder>
          </geometry>
          <surface>
            <contact>
              <ode/>
            </contact>
            <friction>
              <ode>
                <mu>0.9</mu>
                <mu2>0.9</mu2>
              </ode>
            </friction>
            <bounce/>
          </surface>
          <max_contacts>10</max_contacts>
        </collision>
        <collision name='pelvis_collision_pelvis_2'>
          <pose frame=''>0.01 0.042 0.09 0 -0 0</pose>
          <geometry>
            <cylinder>
              <length>0.05</length>
              <radius>0.16</radius>
            </cylinder>
          </geometry>
          <surface>
            <contact>
              <ode/>
            </contact>
            <friction>
              <ode>
                <mu>0.9</mu>
                <mu2>0.9</mu2>
              </ode>
            </friction>
            <bounce/>
          </surface>
          <max_contacts>10</max_contacts>
        </collision>
        <collision name='pelvis_collision_pelvis_3'>
          <pose frame=''>0.01 -0.042 0.09 0 -0 0</pose>
          <geometry>
            <cylinder>
              <length>0.05</length>
              <radius>0.16</radius>
            </cylinder>
          </geometry>
          <surface>
            <contact>
              <ode/>
            </contact>
            <friction>
              <ode>
                <mu>0.9</mu>
                <mu2>0.9</mu2>
              </ode>
            </friction>
            <bounce/>
          </surface>
          <max_contacts>10</max_contacts>
        </collision>
        <collision name='pelvis_collision_pelvis_4'>
          <pose frame=''>-0.1 0 -0.02 0 -0 0</pose>
          <geometry>
            <box>
              <size>0.1 0.15 0.2</size>
            </box>
          </geometry>
          <surface>
            <contact>
              <ode/>
            </contact>
            <friction>
              <ode>
                <mu>0.9</mu>
                <mu2>0.9</mu2>
              </ode>
            </friction>
            <bounce/>
          </surface>
          <max_contacts>10</max_contacts>
        </collision>
        <visual name='pelvis_visual'>
          <pose frame=''>0 0 0 0 -0 0</pose>
          <geometry>
            <mesh>
              <scale>1 1 1</scale>
              <uri>model://atlas_description/meshes_unplugged/pelvis.dae</uri>
            </mesh>
          </geometry>
        </visual>
        <visual name='pelvis_visual_pelvis_1'>
          <pose frame=''>0.0599153 0 -0.01415 0 -0 0</pose>
          <geometry>
            <box>
              <size>0.01 0.01 0.01</size>
            </box>
          </geometry>
        </visual>
        <velocity_decay/>
        <gravity>1</gravity>
        <velocity_decay/>
        <self_collide>0</self_collide>
        <sensor name='imu_sensor' type='imu'>
          <always_on>1</always_on>
          <update_rate>1000</update_rate>
          <imu>
            <noise>
              <type>gaussian</type>
              <rate>
                <mean>0</mean>
                <stddev>0.0002</stddev>
                <bias_mean>7.5e-06</bias_mean>
                <bias_stddev>8e-07</bias_stddev>
              </rate>
              <accel>
                <mean>0</mean>
                <stddev>0.017</stddev>
                <bias_mean>0.1</bias_mean>
                <bias_stddev>0.001</bias_stddev>
              </accel>
            </noise>
          </imu>
          <pose frame=''>0.0599153 0 -0.01415 0 -0 0</pose>
        </sensor>
        <kinematic>0</kinematic>
      </link>
      <link name='ltorso'>
        <pose frame=''>-0.0125 0 0 0 -0 0</pose>
        <inertial>
          <pose frame=''>-0.0112984 -3.15366e-06 0.0746835 0 -0 0</pose>
          <mass>2.27</mass>
          <inertia>
            <ixx>0.0039092</ixx>
            <ixy>-5.04491e-08</ixy>
            <ixz>-0.000342157</ixz>
            <iyy>0.00341694</iyy>
            <iyz>4.87119e-07</iyz>
            <izz>0.00174492</izz>
          </inertia>
        </inertial>
        <visual name='ltorso_visual'>
          <pose frame=''>0 0 0 0 -0 0</pose>
          <geometry>
            <mesh>
              <scale>1 1 1</scale>
              <uri>model://atlas_description/meshes_unplugged/ltorso.dae</uri>
            </mesh>
          </geometry>
        </visual>
        <gravity>1</gravity>
        <velocity_decay/>
        <self_collide>0</self_collide>
        <kinematic>0</kinematic>
      </link>
      <joint name='back_bkz' type='revolute'>
        <child>ltorso</child>
        <parent>pelvis</parent>
        <axis>
          <xyz>0 0 1</xyz>
          <limit>
            <lower>-0.663225</lower>
            <upper>0.663225</upper>
            <effort>106</effort>
            <velocity>12</velocity>
          </limit>
          <dynamics>
            <damping>0.1</damping>
            <friction>0</friction>
            <spring_reference>0</spring_reference>
            <spring_stiffness>0</spring_stiffness>
          </dynamics>
          <use_parent_model_frame>1</use_parent_model_frame>
        </axis>
        <physics>
          <ode>
            <implicit_spring_damper>1</implicit_spring_damper>
            <cfm_damping>1</cfm_damping>
            <limit>
              <cfm>0</cfm>
              <erp>0.2</erp>
            </limit>
          </ode>
        </physics>
      </joint>
      <link name='mtorso'>
        <pose frame=''>-0.0125 0 0.162 0 -0 0</pose>
        <inertial>
          <pose frame=''>-0.00816266 -0.0131245 0.0305974 0 -0 0</pose>
          <mass>0.799</mass>
          <inertia>
            <ixx>0.000454181</ixx>
            <ixy>-6.10764e-05</ixy>
            <ixz>3.94009e-05</ixz>
            <iyy>0.000483282</iyy>
            <iyz>5.27463e-05</iyz>
            <izz>0.000444215</izz>
          </inertia>
        </inertial>
        <collision name='mtorso_collision'>
          <pose frame=''>0 0 -0.02 0 -0 0</pose>
          <geometry>
            <cylinder>
              <length>0.15</length>
              <radius>0.02</radius>
            </cylinder>
          </geometry>
          <surface>
            <contact>
              <ode/>
            </contact>
            <friction>
              <ode>
                <mu>0.9</mu>
                <mu2>0.9</mu2>
              </ode>
            </friction>
            <bounce/>
          </surface>
          <max_contacts>10</max_contacts>
        </collision>
        <visual name='mtorso_visual'>
          <pose frame=''>0 0 0 0 -0 0</pose>
          <geometry>
            <mesh>
              <scale>1 1 1</scale>
              <uri>model://atlas_description/meshes_unplugged/mtorso.dae</uri>
            </mesh>
          </geometry>
        </visual>
        <gravity>1</gravity>
        <velocity_decay/>
        <self_collide>0</self_collide>
        <kinematic>0</kinematic>
      </link>
      <joint name='back_bky' type='revolute'>
        <child>mtorso</child>
        <parent>ltorso</parent>
        <axis>
          <xyz>0 1 0</xyz>
          <limit>
            <lower>-0.219388</lower>
            <upper>0.538783</upper>
            <effort>445</effort>
            <velocity>9</velocity>
          </limit>
          <dynamics>
            <damping>0.1</damping>
            <friction>0</friction>
            <spring_reference>0</spring_reference>
            <spring_stiffness>0</spring_stiffness>
          </dynamics>
          <use_parent_model_frame>1</use_parent_model_frame>
        </axis>
        <physics>
          <ode>
            <implicit_spring_damper>1</implicit_spring_damper>
            <cfm_damping>1</cfm_damping>
            <limit>
              <cfm>0</cfm>
              <erp>0.2</erp>
            </limit>
          </ode>
        </physics>
      </joint>
      <link name='utorso'>
        <pose frame=''>-0.0125 0 0.212 0 -0 0</pose>
        <inertial>
          <pose frame=''>-0.0616866 0.00229456 0.316809 0 -0 0</pose>
          <mass>84.609</mass>
          <inertia>
            <ixx>1.62389</ixx>
            <ixy>-0.0319003</ixy>
            <ixz>0.0816618</ixz>
            <iyy>1.65538</iyy>
            <iyz>0.0472154</iyz>
            <izz>0.577362</izz>
          </inertia>
        </inertial>
        <collision name='utorso_collision'>
          <pose frame=''>-0.102 0 0.25 0 -0 0</pose>
          <geometry>
            <box>
              <size>0.4 0.35 0.5</size>
            </box>
          </geometry>
          <surface>
            <contact>
              <ode/>
            </contact>
            <friction>
              <ode>
                <mu>0.9</mu>
                <mu2>0.9</mu2>
              </ode>
            </friction>
            <bounce/>
          </surface>
          <max_contacts>10</max_contacts>
        </collision>
        <collision name='utorso_collision_utorso_1'>
          <pose frame=''>0.2 0 0.46 0 1.5707 0</pose>
          <geometry>
            <box>
              <size>0.13 0.5 0.1</size>
            </box>
          </geometry>
          <surface>
            <contact>
              <ode/>
            </contact>
            <friction>
              <ode>
                <mu>0.9</mu>
                <mu2>0.9</mu2>
              </ode>
            </friction>
            <bounce/>
          </surface>
          <max_contacts>10</max_contacts>
        </collision>
        <collision name='utorso_collision_utorso_2'>
          <pose frame=''>0.2 0 0.285 3.14159 1.44159 3.14159</pose>
          <geometry>
            <box>
              <size>0.2 0.23 0.1</size>
            </box>
          </geometry>
          <surface>
            <contact>
              <ode/>
            </contact>
            <friction>
              <ode>
                <mu>0.9</mu>
                <mu2>0.9</mu2>
              </ode>
            </friction>
            <bounce/>
          </surface>
          <max_contacts>10</max_contacts>
        </collision>
        <collision name='utorso_collision_utorso_3'>
          <pose frame=''>0.15 0 0.1 3.14159 1.14159 3.14159</pose>
          <geometry>
            <box>
              <size>0.2 0.18 0.1</size>
            </box>
          </geometry>
          <surface>
            <contact>
              <ode/>
            </contact>
            <friction>
              <ode>
                <mu>0.9</mu>
                <mu2>0.9</mu2>
              </ode>
            </friction>
            <bounce/>
          </surface>
          <max_contacts>10</max_contacts>
        </collision>
        <collision name='utorso_collision_utorso_4'>
          <pose frame=''>-0.035 0 0.6265 0 -0 0</pose>
          <geometry>
            <box>
              <size>0.506306 0.341719 0.12</size>
            </box>
          </geometry>
          <surface>
            <contact>
              <ode/>
            </contact>
            <friction>
              <ode>
                <mu>0.9</mu>
                <mu2>0.9</mu2>
              </ode>
            </friction>
            <bounce/>
          </surface>
          <max_contacts>10</max_contacts>
        </collision>
        <collision name='utorso_collision_utorso_5'>
          <pose frame=''>0.208 0 0.8215 1.5707 -0 0</pose>
          <geometry>
            <cylinder>
              <length>0.13</length>
              <radius>0.008</radius>
            </cylinder>
          </geometry>
          <surface>
            <contact>
              <ode/>
            </contact>
            <friction>
              <ode>
                <mu>0.9</mu>
                <mu2>0.9</mu2>
              </ode>
            </friction>
            <bounce/>
          </surface>
          <max_contacts>10</max_contacts>
        </collision>
        <collision name='utorso_collision_utorso_6'>
          <pose frame=''>0.208 -0.125 0.745 -0.38535 0 0</pose>
          <geometry>
            <cylinder>
              <length>0.15</length>
              <radius>0.008</radius>
            </cylinder>
          </geometry>
          <surface>
            <contact>
              <ode/>
            </contact>
            <friction>
              <ode>
                <mu>0.9</mu>
                <mu2>0.9</mu2>
              </ode>
            </friction>
            <bounce/>
          </surface>
          <max_contacts>10</max_contacts>
        </collision>
        <collision name='utorso_collision_utorso_7'>
          <pose frame=''>0.208 0.125 0.745 0.38535 -0 0</pose>
          <geometry>
            <cylinder>
              <length>0.15</length>
              <radius>0.008</radius>
            </cylinder>
          </geometry>
          <surface>
            <contact>
              <ode/>
            </contact>
            <friction>
              <ode>
                <mu>0.9</mu>
                <mu2>0.9</mu2>
              </ode>
            </friction>
            <bounce/>
          </surface>
          <max_contacts>10</max_contacts>
        </collision>
        <collision name='utorso_collision_utorso_8'>
          <pose frame=''>0.063 -0.125 0.745 -0.38535 0 0</pose>
          <geometry>
            <cylinder>
              <length>0.15</length>
              <radius>0.008</radius>
            </cylinder>
          </geometry>
          <surface>
            <contact>
              <ode/>
            </contact>
            <friction>
              <ode>
                <mu>0.9</mu>
                <mu2>0.9</mu2>
              </ode>
            </friction>
            <bounce/>
          </surface>
          <max_contacts>10</max_contacts>
        </collision>
        <collision name='utorso_collision_utorso_9'>
          <pose frame=''>0.063 0.125 0.745 0.38535 -0 0</pose>
          <geometry>
            <cylinder>
              <length>0.15</length>
              <radius>0.008</radius>
            </cylinder>
          </geometry>
          <surface>
            <contact>
              <ode/>
            </contact>
            <friction>
              <ode>
                <mu>0.9</mu>
                <mu2>0.9</mu2>
              </ode>
            </friction>
            <bounce/>
          </surface>
          <max_contacts>10</max_contacts>
        </collision>
        <collision name='utorso_collision_utorso_10'>
          <pose frame=''>0.14 0.06 0.8215 1.5707 5.55112e-17 1.5707</pose>
          <geometry>
            <cylinder>
              <length>0.15</length>
              <radius>0.008</radius>
            </cylinder>
          </geometry>
          <surface>
            <contact>
              <ode/>
            </contact>
            <friction>
              <ode>
                <mu>0.9</mu>
                <mu2>0.9</mu2>
              </ode>
            </friction>
            <bounce/>
          </surface>
          <max_contacts>10</max_contacts>
        </collision>
        <collision name='utorso_collision_utorso_11'>
          <pose frame=''>0.14 -0.06 0.8215 1.5707 5.55112e-17 1.5707</pose>
          <geometry>
            <cylinder>
              <length>0.15</length>
              <radius>0.008</radius>
            </cylinder>
          </geometry>
          <surface>
            <contact>
              <ode/>
            </contact>
            <friction>
              <ode>
                <mu>0.9</mu>
                <mu2>0.9</mu2>
              </ode>
            </friction>
            <bounce/>
          </surface>
          <max_contacts>10</max_contacts>
        </collision>
        <collision name='utorso_collision_utorso_12'>
          <pose frame=''>-0.029 0 0.731 0 -0.65 0</pose>
          <geometry>
            <box>
              <size>0.2 0.25 0.01</size>
            </box>
          </geometry>
          <surface>
            <contact>
              <ode/>
            </contact>
            <friction>
              <ode>
                <mu>0.9</mu>
                <mu2>0.9</mu2>
              </ode>
            </friction>
            <bounce/>
          </surface>
          <max_contacts>10</max_contacts>
        </collision>
        <collision name='utorso_collision_utorso_13'>
          <pose frame=''>0.063 0 0.8215 1.5707 -0 0</pose>
          <geometry>
            <cylinder>
              <length>0.13</length>
              <radius>0.008</radius>
            </cylinder>
          </geometry>
          <surface>
            <contact>
              <ode/>
            </contact>
            <friction>
              <ode>
                <mu>0.9</mu>
                <mu2>0.9</mu2>
              </ode>
            </friction>
            <bounce/>
          </surface>
          <max_contacts>10</max_contacts>
        </collision>
        <collision name='utorso_collision_utorso_14'>
          <pose frame=''>0.261 0.156 0.6215 1.5707 -0 0</pose>
          <geometry>
            <cylinder>
              <length>0.016</length>
              <radius>0.055</radius>
            </cylinder>
          </geometry>
          <surface>
            <contact>
              <ode/>
            </contact>
            <friction>
              <ode>
                <mu>0.9</mu>
                <mu2>0.9</mu2>
              </ode>
            </friction>
            <bounce/>
          </surface>
          <max_contacts>10</max_contacts>
        </collision>
        <collision name='utorso_collision_utorso_15'>
          <pose frame=''>0.261 -0.156 0.6215 1.5707 -0 0</pose>
          <geometry>
            <cylinder>
              <length>0.016</length>
              <radius>0.055</radius>
            </cylinder>
          </geometry>
          <surface>
            <contact>
              <ode/>
            </contact>
            <friction>
              <ode>
                <mu>0.9</mu>
                <mu2>0.9</mu2>
              </ode>
            </friction>
            <bounce/>
          </surface>
          <max_contacts>10</max_contacts>
        </collision>
        <visual name='utorso_visual'>
          <pose frame=''>0 0 0 0 -0 0</pose>
          <geometry>
            <mesh>
              <scale>1 1 1</scale>
              <uri>model://atlas_description/meshes_unplugged/utorso.dae</uri>
            </mesh>
          </geometry>
        </visual>
        <visual name='utorso_visual_utorso_1'>
          <pose frame=''>0.155 0.121 0.785 0 -0 1.309</pose>
          <geometry>
            <box>
              <size>0.01 0.01 0.01</size>
            </box>
          </geometry>
        </visual>
        <visual name='utorso_visual_utorso_2'>
          <pose frame=''>0.155 -0.121 0.785 0 0 -1.309</pose>
          <geometry>
            <box>
              <size>0.01 0.01 0.01</size>
            </box>
          </geometry>
        </visual>
        <velocity_decay/>
        <velocity_decay/>
        <sensor name='l_situational_awareness_camera_sensor' type='camera'>
          <update_rate>60</update_rate>
          <camera name='l_situational_awareness_camera'>
            <pose frame=''>0 0 0 0 -0 0</pose>
            <horizontal_fov>2</horizontal_fov>
            <image>
              <width>1280</width>
              <height>1024</height>
              <format>R8G8B8</format>
            </image>
            <clip>
              <near>0.02</near>
              <far>300</far>
            </clip>
            <noise>
              <type>gaussian</type>
              <mean>0</mean>
              <stddev>0.007</stddev>
            </noise>
          </camera>
          <plugin name='l_situational_awareness_camera_controller' filename='libgazebo_ros_camera.so'>
            <alwaysOn>true</alwaysOn>
            <updateRate>0.0</updateRate>
            <cameraName>l_situational_awareness_camera</cameraName>
            <imageTopicName>image_raw</imageTopicName>
            <cameraInfoTopicName>camera_info</cameraInfoTopicName>
            <frameName>l_situational_awareness_camera_optical_frame</frameName>
            <hackBaseline>0.0</hackBaseline>
            <distortionK1>0.0</distortionK1>
            <distortionK2>0.0</distortionK2>
            <distortionK3>0.0</distortionK3>
            <distortionT1>0.0</distortionT1>
            <distortionT2>0.0</distortionT2>
          </plugin>
          <pose frame=''>0.155 0.121 0.785 0 -0 1.309</pose>
        </sensor>
        <gravity>1</gravity>
        <velocity_decay/>
        <self_collide>0</self_collide>
        <sensor name='r_situational_awareness_camera_sensor' type='camera'>
          <update_rate>60</update_rate>
          <camera name='r_situational_awareness_camera'>
            <pose frame=''>0 0 0 0 -0 0</pose>
            <horizontal_fov>2</horizontal_fov>
            <image>
              <width>1280</width>
              <height>1024</height>
              <format>R8G8B8</format>
            </image>
            <clip>
              <near>0.02</near>
              <far>300</far>
            </clip>
            <noise>
              <type>gaussian</type>
              <mean>0</mean>
              <stddev>0.007</stddev>
            </noise>
          </camera>
          <plugin name='r_situational_awareness_camera_controller' filename='libgazebo_ros_camera.so'>
            <alwaysOn>true</alwaysOn>
            <updateRate>0.0</updateRate>
            <cameraName>r_situational_awareness_camera</cameraName>
            <imageTopicName>image_raw</imageTopicName>
            <cameraInfoTopicName>camera_info</cameraInfoTopicName>
            <frameName>r_situational_awareness_camera_optical_frame</frameName>
            <hackBaseline>0.0</hackBaseline>
            <distortionK1>0.0</distortionK1>
            <distortionK2>0.0</distortionK2>
            <distortionK3>0.0</distortionK3>
            <distortionT1>0.0</distortionT1>
            <distortionT2>0.0</distortionT2>
          </plugin>
          <pose frame=''>0.155 -0.121 0.785 0 0 -1.309</pose>
        </sensor>
        <kinematic>0</kinematic>
      </link>
      <joint name='back_bkx' type='revolute'>
        <child>utorso</child>
        <parent>mtorso</parent>
        <axis>
          <xyz>1 0 0</xyz>
          <limit>
            <lower>-0.523599</lower>
            <upper>0.523599</upper>
            <effort>300</effort>
            <velocity>12</velocity>
          </limit>
          <dynamics>
            <damping>0.1</damping>
            <friction>0</friction>
            <spring_reference>0</spring_reference>
            <spring_stiffness>0</spring_stiffness>
          </dynamics>
          <use_parent_model_frame>1</use_parent_model_frame>
        </axis>
        <physics>
          <ode>
            <implicit_spring_damper>1</implicit_spring_damper>
            <cfm_damping>1</cfm_damping>
            <limit>
              <cfm>0</cfm>
              <erp>0.2</erp>
            </limit>
          </ode>
        </physics>
      </joint>
      <link name='l_clav'>
        <pose frame=''>0.1281 0.2256 0.6896 0 -0 -3.14159</pose>
        <inertial>
          <pose frame=''>0 0 -0.084 0 -0 0</pose>
          <mass>4.466</mass>
          <inertia>
            <ixx>0.011</ixx>
            <ixy>0</ixy>
            <ixz>0</ixz>
            <iyy>0.009</iyy>
            <iyz>0.004</iyz>
            <izz>0.004</izz>
          </inertia>
        </inertial>
        <collision name='l_clav_collision'>
          <pose frame=''>0 -0.11 -0.248 -2.65359e-06 1.57079 -2.65359e-06</pose>
          <geometry>
            <cylinder>
              <length>0.1525</length>
              <radius>0.0555</radius>
            </cylinder>
          </geometry>
          <surface>
            <contact>
              <ode/>
            </contact>
            <friction>
              <ode>
                <mu>0.9</mu>
                <mu2>0.9</mu2>
              </ode>
            </friction>
            <bounce/>
          </surface>
          <max_contacts>10</max_contacts>
        </collision>
        <collision name='l_clav_collision_l_clav_1'>
          <pose frame=''>0.005 -0.015 -0.08 0 -0 0</pose>
          <geometry>
            <cylinder>
              <length>0.26</length>
              <radius>0.067</radius>
            </cylinder>
          </geometry>
          <surface>
            <contact>
              <ode/>
            </contact>
            <friction>
              <ode>
                <mu>0.9</mu>
                <mu2>0.9</mu2>
              </ode>
            </friction>
            <bounce/>
          </surface>
          <max_contacts>10</max_contacts>
        </collision>
        <collision name='l_clav_collision_l_clav_2'>
          <pose frame=''>0.004 -0.064 -0.247 1.05 -0 0</pose>
          <geometry>
            <box>
              <size>0.1 0.07 0.072</size>
            </box>
          </geometry>
          <surface>
            <contact>
              <ode/>
            </contact>
            <friction>
              <ode>
                <mu>0.9</mu>
                <mu2>0.9</mu2>
              </ode>
            </friction>
            <bounce/>
          </surface>
          <max_contacts>10</max_contacts>
        </collision>
        <visual name='l_clav_visual'>
          <pose frame=''>0 0 0 0 -0 0</pose>
          <geometry>
            <mesh>
              <scale>1 1 1</scale>
              <uri>model://atlas_description/meshes_unplugged/r_clav.dae</uri>
            </mesh>
          </geometry>
        </visual>
        <gravity>1</gravity>
        <velocity_decay/>
        <self_collide>0</self_collide>
        <kinematic>0</kinematic>
      </link>
      <joint name='l_arm_shz' type='revolute'>
        <child>l_clav</child>
        <parent>utorso</parent>
        <axis>
          <xyz>0 0 1</xyz>
          <limit>
            <lower>-1.5708</lower>
            <upper>0.785398</upper>
            <effort>87</effort>
            <velocity>12</velocity>
          </limit>
          <dynamics>
            <damping>0.1</damping>
            <friction>0</friction>
            <spring_reference>0</spring_reference>
            <spring_stiffness>0</spring_stiffness>
          </dynamics>
          <use_parent_model_frame>1</use_parent_model_frame>
        </axis>
        <physics>
          <ode>
            <implicit_spring_damper>1</implicit_spring_damper>
            <cfm_damping>1</cfm_damping>
            <limit>
              <cfm>0</cfm>
              <erp>0.2</erp>
            </limit>
          </ode>
        </physics>
      </joint>
      <link name='l_scap'>
        <pose frame=''>0.1281 0.3356 0.4446 0 -0 -3.14159</pose>
        <inertial>
          <pose frame=''>0 0 0 0 -0 0</pose>
          <mass>3.899</mass>
          <inertia>
            <ixx>0.00319</ixx>
            <ixy>0</ixy>
            <ixz>0</ixz>
            <iyy>0.00583</iyy>
            <iyz>0</iyz>
            <izz>0.00583</izz>
          </inertia>
        </inertial>
        <collision name='l_scap_collision'>
          <pose frame=''>-0.005 -0.115 -0.014 1.5708 -0 0</pose>
          <geometry>
            <cylinder>
              <length>0.105</length>
              <radius>0.057</radius>
            </cylinder>
          </geometry>
          <surface>
            <contact>
              <ode/>
            </contact>
            <friction>
              <ode>
                <mu>0.9</mu>
                <mu2>0.9</mu2>
              </ode>
            </friction>
            <bounce/>
          </surface>
          <max_contacts>10</max_contacts>
        </collision>
        <collision name='l_scap_collision_l_scap_1'>
          <pose frame=''>-0.005 -0.075 -0.015 0 -0 0</pose>
          <geometry>
            <box>
              <size>0.16 0.17 0.08</size>
            </box>
          </geometry>
          <surface>
            <contact>
              <ode/>
            </contact>
            <friction>
              <ode>
                <mu>0.9</mu>
                <mu2>0.9</mu2>
              </ode>
            </friction>
            <bounce/>
          </surface>
          <max_contacts>10</max_contacts>
        </collision>
        <collision name='l_scap_collision_l_scap_2'>
          <pose frame=''>0.076 -0.0615 0.0128 2.25 -0 0</pose>
          <geometry>
            <box>
              <size>0.02 0.029 0.018</size>
            </box>
          </geometry>
          <surface>
            <contact>
              <ode/>
            </contact>
            <friction>
              <ode>
                <mu>0.9</mu>
                <mu2>0.9</mu2>
              </ode>
            </friction>
            <bounce/>
          </surface>
          <max_contacts>10</max_contacts>
        </collision>
        <collision name='l_scap_collision_l_scap_3'>
          <pose frame=''>-0.075 0.015 0.019 1 -0 0</pose>
          <geometry>
            <box>
              <size>0.028 0.09 0.05</size>
            </box>
          </geometry>
          <surface>
            <contact>
              <ode/>
            </contact>
            <friction>
              <ode>
                <mu>0.9</mu>
                <mu2>0.9</mu2>
              </ode>
            </friction>
            <bounce/>
          </surface>
          <max_contacts>10</max_contacts>
        </collision>
        <visual name='l_scap_visual'>
          <pose frame=''>0 0 0 0 -0 0</pose>
          <geometry>
            <mesh>
              <scale>1 1 1</scale>
              <uri>model://atlas_description/meshes_unplugged/r_scap.dae</uri>
            </mesh>
          </geometry>
        </visual>
        <gravity>1</gravity>
        <velocity_decay/>
        <self_collide>0</self_collide>
        <kinematic>0</kinematic>
      </link>
      <joint name='l_arm_shx' type='revolute'>
        <child>l_scap</child>
        <parent>l_clav</parent>
        <axis>
          <xyz>1 0 0</xyz>
          <limit>
            <lower>-1.5708</lower>
            <upper>1.5708</upper>
            <effort>99</effort>
            <velocity>12</velocity>
          </limit>
          <dynamics>
            <damping>0.1</damping>
            <friction>0</friction>
            <spring_reference>0</spring_reference>
            <spring_stiffness>0</spring_stiffness>
          </dynamics>
          <use_parent_model_frame>1</use_parent_model_frame>
        </axis>
        <physics>
          <ode>
            <implicit_spring_damper>1</implicit_spring_damper>
            <cfm_damping>1</cfm_damping>
            <limit>
              <cfm>0</cfm>
              <erp>0.2</erp>
            </limit>
          </ode>
        </physics>
      </joint>
      <link name='l_uarm'>
        <pose frame=''>0.1281 0.5226 0.4286 0 -0 -3.14159</pose>
        <inertial>
          <pose frame=''>0 0.065 0 0 -0 0</pose>
          <mass>4.386</mass>
          <inertia>
            <ixx>0.00656</ixx>
            <ixy>0</ixy>
            <ixz>0</ixz>
            <iyy>0.00358</iyy>
            <iyz>0</iyz>
            <izz>0.00656</izz>
          </inertia>
        </inertial>
        <collision name='l_uarm_collision'>
          <pose frame=''>0 -0.035 -0.005 1.5708 -0 0</pose>
          <geometry>
            <cylinder>
              <length>0.11</length>
              <radius>0.065</radius>
            </cylinder>
          </geometry>
          <surface>
            <contact>
              <ode/>
            </contact>
            <friction>
              <ode>
                <mu>0.9</mu>
                <mu2>0.9</mu2>
              </ode>
            </friction>
            <bounce/>
          </surface>
          <max_contacts>10</max_contacts>
        </collision>
        <collision name='l_uarm_collision_l_uarm_1'>
          <pose frame=''>-0.01 -0.043 0.002 -2.65359e-06 1.57079 -2.65359e-06</pose>
          <geometry>
            <box>
              <size>0.05 0.07 0.15</size>
            </box>
          </geometry>
          <surface>
            <contact>
              <ode/>
            </contact>
            <friction>
              <ode>
                <mu>0.9</mu>
                <mu2>0.9</mu2>
              </ode>
            </friction>
            <bounce/>
          </surface>
          <max_contacts>10</max_contacts>
        </collision>
        <visual name='l_uarm_visual'>
          <pose frame=''>0 0 0 0 -0 0</pose>
          <geometry>
            <mesh>
              <scale>1 1 1</scale>
              <uri>model://atlas_description/meshes_unplugged/r_uarm.dae</uri>
            </mesh>
          </geometry>
        </visual>
        <gravity>1</gravity>
        <velocity_decay/>
        <self_collide>0</self_collide>
        <kinematic>0</kinematic>
      </link>
      <joint name='l_arm_ely' type='revolute'>
        <child>l_uarm</child>
        <parent>l_scap</parent>
        <axis>
          <xyz>-0 1 0</xyz>
          <limit>
            <lower>0</lower>
            <upper>3.14159</upper>
            <effort>63</effort>
            <velocity>12</velocity>
          </limit>
          <dynamics>
            <damping>0.1</damping>
            <friction>0</friction>
            <spring_reference>0</spring_reference>
            <spring_stiffness>0</spring_stiffness>
          </dynamics>
          <use_parent_model_frame>1</use_parent_model_frame>
        </axis>
        <physics>
          <ode>
            <implicit_spring_damper>1</implicit_spring_damper>
            <cfm_damping>1</cfm_damping>
            <limit>
              <cfm>0</cfm>
              <erp>0.2</erp>
            </limit>
          </ode>
        </physics>
      </joint>
      <link name='l_larm'>
        <pose frame=''>0.1281 0.6416 0.4378 0 -0 -3.14159</pose>
        <inertial>
          <pose frame=''>0 0 0 0 -0 0</pose>
          <mass>3.248</mass>
          <inertia>
            <ixx>0.00265</ixx>
            <ixy>0</ixy>
            <ixz>0</ixz>
            <iyy>0.00446</iyy>
            <iyz>0</iyz>
            <izz>0.00446</izz>
          </inertia>
        </inertial>
        <collision name='l_larm_collision'>
          <pose frame=''>0 -0.075 -0.01 -1.5708 0 0</pose>
          <geometry>
            <cylinder>
              <length>0.04</length>
              <radius>0.051</radius>
            </cylinder>
          </geometry>
          <surface>
            <contact>
              <ode/>
            </contact>
            <friction>
              <ode>
                <mu>0.9</mu>
                <mu2>0.9</mu2>
              </ode>
            </friction>
            <bounce/>
          </surface>
          <max_contacts>10</max_contacts>
        </collision>
        <collision name='l_larm_collision_l_larm_1'>
          <pose frame=''>-0.012 0 0.0025 -2.65359e-06 1.57079 -2.65359e-06</pose>
          <geometry>
            <cylinder>
              <length>0.147</length>
              <radius>0.045</radius>
            </cylinder>
          </geometry>
          <surface>
            <contact>
              <ode/>
            </contact>
            <friction>
              <ode>
                <mu>0.9</mu>
                <mu2>0.9</mu2>
              </ode>
            </friction>
            <bounce/>
          </surface>
          <max_contacts>10</max_contacts>
        </collision>
        <collision name='l_larm_collision_l_larm_2'>
          <pose frame=''>-0.07 -0.077 -0.015 0 -0 0</pose>
          <geometry>
            <box>
              <size>0.025 0.155 0.07</size>
            </box>
          </geometry>
          <surface>
            <contact>
              <ode/>
            </contact>
            <friction>
              <ode>
                <mu>0.9</mu>
                <mu2>0.9</mu2>
              </ode>
            </friction>
            <bounce/>
          </surface>
          <max_contacts>10</max_contacts>
        </collision>
        <collision name='l_larm_collision_l_larm_3'>
          <pose frame=''>0.05 -0.067 -0.009 0 -0 0</pose>
          <geometry>
            <box>
              <size>0.025 0.06 0.06</size>
            </box>
          </geometry>
          <surface>
            <contact>
              <ode/>
            </contact>
            <friction>
              <ode>
                <mu>0.9</mu>
                <mu2>0.9</mu2>
              </ode>
            </friction>
            <bounce/>
          </surface>
          <max_contacts>10</max_contacts>
        </collision>
        <collision name='l_larm_collision_l_larm_4'>
          <pose frame=''>-0.032 -0.071 -0.06 0 -0 0</pose>
          <geometry>
            <box>
              <size>0.04 0.115 0.05</size>
            </box>
          </geometry>
          <surface>
            <contact>
              <ode/>
            </contact>
            <friction>
              <ode>
                <mu>0.9</mu>
                <mu2>0.9</mu2>
              </ode>
            </friction>
            <bounce/>
          </surface>
          <max_contacts>10</max_contacts>
        </collision>
        <collision name='l_larm_collision_l_larm_5'>
          <pose frame=''>0.03 0.01 -0.05 0 -0 0</pose>
          <geometry>
            <box>
              <size>0.045 0.055 0.023</size>
            </box>
          </geometry>
          <surface>
            <contact>
              <ode/>
            </contact>
            <friction>
              <ode>
                <mu>0.9</mu>
                <mu2>0.9</mu2>
              </ode>
            </friction>
            <bounce/>
          </surface>
          <max_contacts>10</max_contacts>
        </collision>
        <visual name='l_larm_visual'>
          <pose frame=''>0 0 0 0 -0 0</pose>
          <geometry>
            <mesh>
              <scale>1 1 1</scale>
              <uri>model://atlas_description/meshes_unplugged/r_larm.dae</uri>
            </mesh>
          </geometry>
        </visual>
        <gravity>1</gravity>
        <velocity_decay/>
        <self_collide>0</self_collide>
        <kinematic>0</kinematic>
      </link>
      <joint name='l_arm_elx' type='revolute'>
        <child>l_larm</child>
        <parent>l_uarm</parent>
        <axis>
          <xyz>1 0 0</xyz>
          <limit>
            <lower>0</lower>
            <upper>2.35619</upper>
            <effort>112</effort>
            <velocity>12</velocity>
          </limit>
          <dynamics>
            <damping>0.1</damping>
            <friction>0</friction>
            <spring_reference>0</spring_reference>
            <spring_stiffness>0</spring_stiffness>
          </dynamics>
          <use_parent_model_frame>1</use_parent_model_frame>
        </axis>
        <physics>
          <ode>
            <implicit_spring_damper>1</implicit_spring_damper>
            <cfm_damping>1</cfm_damping>
            <limit>
              <cfm>0</cfm>
              <erp>0.2</erp>
            </limit>
          </ode>
        </physics>
      </joint>
      <link name='l_ufarm'>
        <pose frame=''>0.1281 0.94115 0.42859 3.14159 -2.06823e-13 2.06823e-13</pose>
        <inertial>
          <pose frame=''>0.00015 0.08296 0.00037 0 -0 0</pose>
          <mass>2.4798</mass>
          <inertia>
            <ixx>0.012731</ixx>
            <ixy>0</ixy>
            <ixz>0</ixz>
            <iyy>0.002857</iyy>
            <iyz>0</iyz>
            <izz>0.011948</izz>
          </inertia>
        </inertial>
        <collision name='l_ufarm_collision'>
          <pose frame=''>0 0.15 0 1.57 -0 0</pose>
          <geometry>
            <cylinder>
              <length>0.1</length>
              <radius>0.053</radius>
            </cylinder>
          </geometry>
          <surface>
            <contact>
              <ode/>
            </contact>
            <friction>
              <ode>
                <mu>0.9</mu>
                <mu2>0.9</mu2>
              </ode>
            </friction>
            <bounce/>
          </surface>
          <max_contacts>10</max_contacts>
        </collision>
        <collision name='l_ufarm_collision_l_ufarm_1'>
          <pose frame=''>-0.001 0.07 0 -2.65359e-06 1.57079 -2.65359e-06</pose>
          <geometry>
            <box>
              <size>0.08 0.09 0.11</size>
            </box>
          </geometry>
          <surface>
            <contact>
              <ode/>
            </contact>
            <friction>
              <ode>
                <mu>0.9</mu>
                <mu2>0.9</mu2>
              </ode>
            </friction>
            <bounce/>
          </surface>
          <max_contacts>10</max_contacts>
        </collision>
        <collision name='l_ufarm_collision_l_ufarm_2'>
          <pose frame=''>0 0.005 0 0 1.57 0</pose>
          <geometry>
            <cylinder>
              <length>0.125</length>
              <radius>0.04</radius>
            </cylinder>
          </geometry>
          <surface>
            <contact>
              <ode/>
            </contact>
            <friction>
              <ode>
                <mu>0.9</mu>
                <mu2>0.9</mu2>
              </ode>
            </friction>
            <bounce/>
          </surface>
          <max_contacts>10</max_contacts>
        </collision>
        <visual name='l_ufarm_visual'>
          <pose frame=''>0 0 0 0 -0 0</pose>
          <geometry>
            <mesh>
              <scale>1 1 1</scale>
              <uri>model://atlas_description/meshes_unplugged/r_farm.dae</uri>
            </mesh>
          </geometry>
        </visual>
        <gravity>1</gravity>
        <velocity_decay/>
        <self_collide>0</self_collide>
        <kinematic>0</kinematic>
      </link>
      <joint name='l_arm_wry' type='revolute'>
        <child>l_ufarm</child>
        <parent>l_larm</parent>
        <axis>
          <xyz>-0 1 0</xyz>
          <limit>
            <lower>-3.011</lower>
            <upper>3.011</upper>
            <effort>25</effort>
            <velocity>10</velocity>
          </limit>
          <dynamics>
            <damping>0.1</damping>
            <friction>0</friction>
            <spring_reference>0</spring_reference>
            <spring_stiffness>0</spring_stiffness>
          </dynamics>
          <use_parent_model_frame>1</use_parent_model_frame>
        </axis>
        <physics>
          <ode>
            <implicit_spring_damper>1</implicit_spring_damper>
            <cfm_damping>1</cfm_damping>
            <limit>
              <cfm>0</cfm>
              <erp>0.2</erp>
            </limit>
          </ode>
        </physics>
      </joint>
      <link name='l_lfarm'>
        <pose frame=''>0.1281 0.94115 0.42859 3.14159 -2.06823e-13 2.06823e-13</pose>
        <inertial>
          <pose frame=''>0.00017 -0.02515 0.00163 0 -0 0</pose>
          <mass>0.648</mass>
          <inertia>
            <ixx>0.000764</ixx>
            <ixy>0</ixy>
            <ixz>0</ixz>
            <iyy>0.000429</iyy>
            <iyz>0</iyz>
            <izz>0.000825</izz>
          </inertia>
        </inertial>
        <collision name='l_lfarm_collision'>
          <pose frame=''>0 -0.104 0 1.5708 -0 0</pose>
          <geometry>
            <cylinder>
              <length>0.02</length>
              <radius>0.031</radius>
            </cylinder>
          </geometry>
          <surface>
            <contact>
              <ode/>
            </contact>
            <friction>
              <ode>
                <mu>0.9</mu>
                <mu2>0.9</mu2>
              </ode>
            </friction>
            <bounce/>
          </surface>
          <max_contacts>10</max_contacts>
        </collision>
        <collision name='l_lfarm_collision_l_lfarm_1'>
          <pose frame=''>0 -0.087 0 1.5708 -0 0</pose>
          <geometry>
            <cylinder>
              <length>0.015</length>
              <radius>0.045</radius>
            </cylinder>
          </geometry>
          <surface>
            <contact>
              <ode/>
            </contact>
            <friction>
              <ode>
                <mu>0.9</mu>
                <mu2>0.9</mu2>
              </ode>
            </friction>
            <bounce/>
          </surface>
          <max_contacts>10</max_contacts>
        </collision>
        <collision name='l_lfarm_collision_l_lfarm_2'>
          <pose frame=''>0 -0.075 0 1.5708 -0 0</pose>
          <geometry>
            <cylinder>
              <length>0.015</length>
              <radius>0.052</radius>
            </cylinder>
          </geometry>
          <surface>
            <contact>
              <ode/>
            </contact>
            <friction>
              <ode>
                <mu>0.9</mu>
                <mu2>0.9</mu2>
              </ode>
            </friction>
            <bounce/>
          </surface>
          <max_contacts>10</max_contacts>
        </collision>
        <collision name='l_lfarm_collision_l_lfarm_3'>
          <pose frame=''>0 -0.052 0 1.5708 -0 0</pose>
          <geometry>
            <cylinder>
              <length>0.027</length>
              <radius>0.043</radius>
            </cylinder>
          </geometry>
          <surface>
            <contact>
              <ode/>
            </contact>
            <friction>
              <ode>
                <mu>0.9</mu>
                <mu2>0.9</mu2>
              </ode>
            </friction>
            <bounce/>
          </surface>
          <max_contacts>10</max_contacts>
        </collision>
        <visual name='l_lfarm_visual'>
          <pose frame=''>0 0 0 3.14159 -2.06823e-13 3.14159</pose>
          <geometry>
            <mesh>
              <scale>1 1 1</scale>
              <uri>model://atlas_description/meshes_unplugged/r_hand.dae</uri>
            </mesh>
          </geometry>
        </visual>
        <gravity>1</gravity>
        <velocity_decay/>
        <self_collide>0</self_collide>
        <kinematic>0</kinematic>
      </link>
      <joint name='l_arm_wrx' type='revolute'>
        <child>l_lfarm</child>
        <parent>l_ufarm</parent>
        <axis>
          <xyz>1 0 0</xyz>
          <limit>
            <lower>-1.7628</lower>
            <upper>1.7628</upper>
            <effort>25</effort>
            <velocity>10</velocity>
          </limit>
          <dynamics>
            <damping>0.1</damping>
            <friction>0</friction>
            <spring_reference>0</spring_reference>
            <spring_stiffness>0</spring_stiffness>
          </dynamics>
          <use_parent_model_frame>1</use_parent_model_frame>
        </axis>
        <physics>
          <provide_feedback>1</provide_feedback>
          <ode>
            <provide_feedback>1</provide_feedback>
            <limit>
              <cfm>0</cfm>
              <erp>0.2</erp>
            </limit>
            <implicit_spring_damper>1</implicit_spring_damper>
            <cfm_damping>1</cfm_damping>
          </ode>
        </physics>
      </joint>
      <link name='l_hand'>
        <pose frame=''>0.1281 0.94115 0.42859 0 4.13646e-13 -3.14159</pose>
        <inertial>
          <pose frame=''>0.00016 -0.08159 2e-05 0 -0 0</pose>
          <mass>0.5839</mass>
          <inertia>
            <ixx>0.000388</ixx>
            <ixy>0</ixy>
            <ixz>0</ixz>
            <iyy>0.000477</iyy>
            <iyz>0</iyz>
            <izz>0.000379</izz>
          </inertia>
        </inertial>
        <gravity>1</gravity>
        <velocity_decay/>
        <self_collide>0</self_collide>
        <kinematic>0</kinematic>
      </link>
      <joint name='l_arm_wry2' type='revolute'>
        <child>l_hand</child>
        <parent>l_lfarm</parent>
        <axis>
          <xyz>0 -1 0</xyz>
          <limit>
            <lower>-2.9671</lower>
            <upper>2.9671</upper>
            <effort>25</effort>
            <velocity>10</velocity>
          </limit>
          <dynamics>
            <damping>0.1</damping>
            <friction>0</friction>
            <spring_reference>0</spring_reference>
            <spring_stiffness>0</spring_stiffness>
          </dynamics>
          <use_parent_model_frame>1</use_parent_model_frame>
        </axis>
        <physics>
          <ode>
            <implicit_spring_damper>1</implicit_spring_damper>
            <cfm_damping>1</cfm_damping>
            <limit>
              <cfm>0</cfm>
              <erp>0.2</erp>
            </limit>
          </ode>
        </physics>
      </joint>
      <link name='head'>
        <pose frame=''>0.2421 0 0.8335 0 -0 0</pose>
        <inertial>
          <pose frame=''>-0.0754942 3.38765e-05 0.0277411 0 -0 0</pose>
          <mass>1.41991</mass>
          <inertia>
            <ixx>0.00397627</ixx>
            <ixy>-1.51324e-06</ixy>
            <ixz>-0.000892818</ixz>
            <iyy>0.00412515</iyy>
            <iyz>-6.83342e-07</iyz>
            <izz>0.00353178</izz>
          </inertia>
        </inertial>
        <collision name='head_collision'>
          <pose frame=''>-0.0503 0 -0.00195 0 -0 0</pose>
          <geometry>
            <box>
              <size>0.1311 0.12 0.0591</size>
            </box>
          </geometry>
          <surface>
            <contact>
              <ode/>
            </contact>
            <friction>
              <ode>
                <mu>0.9</mu>
                <mu2>0.9</mu2>
              </ode>
            </friction>
            <bounce/>
          </surface>
          <max_contacts>10</max_contacts>
        </collision>
        <collision name='head_collision_head_1'>
          <pose frame=''>-0.093 0 0.0868 0 -0 0</pose>
          <geometry>
            <box>
              <size>0.0468 0.12 0.1184</size>
            </box>
          </geometry>
          <surface>
            <contact>
              <ode/>
            </contact>
            <friction>
              <ode>
                <mu>0.9</mu>
                <mu2>0.9</mu2>
              </ode>
            </friction>
            <bounce/>
          </surface>
          <max_contacts>10</max_contacts>
        </collision>
        <visual name='head_visual'>
          <pose frame=''>0 0 0 0 -0 0</pose>
          <geometry>
            <mesh>
              <scale>1 1 1</scale>
              <uri>model://multisense_sl_description/meshes/head.dae</uri>
            </mesh>
          </geometry>
        </visual>
        <visual name='head_visual_head_1'>
          <pose frame=''>-0.0475 0.035 0 0 -0 0</pose>
          <geometry>
            <box>
              <size>0.01 0.01 0.01</size>
            </box>
          </geometry>
        </visual>
        <velocity_decay/>
        <velocity_decay/>
        <sensor name='head_imu_sensor' type='imu'>
          <always_on>1</always_on>
          <update_rate>1000</update_rate>
          <imu>
            <noise>
              <type>gaussian</type>
              <rate>
                <mean>0</mean>
                <stddev>0.0002</stddev>
                <bias_mean>7.5e-06</bias_mean>
                <bias_stddev>8e-07</bias_stddev>
              </rate>
              <accel>
                <mean>0</mean>
                <stddev>0.017</stddev>
                <bias_mean>0.1</bias_mean>
                <bias_stddev>0.001</bias_stddev>
              </accel>
            </noise>
          </imu>
          <pose frame=''>-0.0475 0.035 0 0 -0 0</pose>
        </sensor>
        <gravity>1</gravity>
        <velocity_decay/>
        <self_collide>0</self_collide>
        <sensor name='stereo_camera' type='multicamera'>
          <update_rate>10</update_rate>
          <camera name='left'>
            <horizontal_fov>1.39626</horizontal_fov>
            <image>
              <width>1024</width>
              <height>544</height>
              <format>R8G8B8</format>
            </image>
            <clip>
              <near>0.02</near>
              <far>300</far>
            </clip>
            <noise>
              <type>gaussian</type>
              <mean>0</mean>
              <stddev>0.007</stddev>
            </noise>
          </camera>
          <camera name='right'>
            <pose frame=''>0 -0.07 0 0 -0 0</pose>
            <horizontal_fov>1.39626</horizontal_fov>
            <image>
              <width>1024</width>
              <height>544</height>
              <format>R8G8B8</format>
            </image>
            <clip>
              <near>0.02</near>
              <far>300</far>
            </clip>
            <noise>
              <type>gaussian</type>
              <mean>0</mean>
              <stddev>0.007</stddev>
            </noise>
          </camera>
          <plugin name='stereo_camera_controller' filename='libgazebo_ros_multicamera.so'>
            <alwaysOn>true</alwaysOn>
            <updateRate>0.0</updateRate>
            <cameraName>multisense/camera</cameraName>
            <imageTopicName>image_raw</imageTopicName>
            <cameraInfoTopicName>camera_info</cameraInfoTopicName>
            <frameName>left_camera_optical_frame</frameName>
            <hackBaseline>0.07</hackBaseline>
            <distortionK1>0.0</distortionK1>
            <distortionK2>0.0</distortionK2>
            <distortionK3>0.0</distortionK3>
            <distortionT1>0.0</distortionT1>
            <distortionT2>0.0</distortionT2>
          </plugin>
          <pose frame=''>0 0.035 -0.002 0 -0 0</pose>
        </sensor>
        <kinematic>0</kinematic>
      </link>
      <joint name='neck_ry' type='revolute'>
        <child>head</child>
        <parent>utorso</parent>
        <axis>
          <xyz>0 1 0</xyz>
          <limit>
            <lower>-0.602139</lower>
            <upper>1.14319</upper>
            <effort>25</effort>
            <velocity>6.28</velocity>
          </limit>
          <dynamics>
            <damping>0.1</damping>
            <friction>0</friction>
            <spring_reference>0</spring_reference>
            <spring_stiffness>0</spring_stiffness>
          </dynamics>
          <use_parent_model_frame>1</use_parent_model_frame>
        </axis>
        <physics>
          <ode>
            <implicit_spring_damper>1</implicit_spring_damper>
            <cfm_damping>1</cfm_damping>
            <limit>
              <cfm>0</cfm>
              <erp>0.2</erp>
            </limit>
          </ode>
        </physics>
      </joint>
      <link name='hokuyo_link'>
        <pose frame=''>0.1975 0 0.9215 0 -0 0</pose>
        <inertial>
          <pose frame=''>0.0324349 0.0004084 -0.0041783 0 -0 0</pose>
          <mass>0.057664</mass>
          <inertia>
            <ixx>3.8183e-05</ixx>
            <ixy>4.9927e-08</ixy>
            <ixz>1.1003e-05</ixz>
            <iyy>4.3437e-05</iyy>
            <iyz>-9.8165e-09</iyz>
            <izz>4.2686e-05</izz>
          </inertia>
        </inertial>
        <collision name='hokuyo_link_collision'>
          <pose frame=''>0.01885 0 -0.02119 0 -0 0</pose>
          <geometry>
            <box>
              <size>0.08 0.06 0.04238</size>
            </box>
          </geometry>
          <surface>
            <contact>
              <ode/>
            </contact>
            <friction>
              <ode>
                <mu>0.9</mu>
                <mu2>0.9</mu2>
              </ode>
            </friction>
            <bounce/>
          </surface>
          <max_contacts>10</max_contacts>
        </collision>
        <collision name='hokuyo_link_collision_hokuyo_link_1'>
          <pose frame=''>0.03 0 0.0235 0 -0 0</pose>
          <geometry>
            <cylinder>
              <length>0.047</length>
              <radius>0.024425</radius>
            </cylinder>
          </geometry>
          <surface>
            <contact>
              <ode/>
            </contact>
            <friction>
              <ode>
                <mu>0.9</mu>
                <mu2>0.9</mu2>
              </ode>
            </friction>
            <bounce/>
          </surface>
          <max_contacts>10</max_contacts>
        </collision>
        <visual name='hokuyo_link_visual'>
          <pose frame=''>0.045 -0.0261018 -0.0834237 -0.314 0 0</pose>
          <geometry>
            <mesh>
              <scale>1 1 1</scale>
              <uri>model://multisense_sl_description/meshes/head_camera.dae</uri>
            </mesh>
          </geometry>
        </visual>
        <velocity_decay/>
        <gravity>1</gravity>
        <velocity_decay/>
        <self_collide>0</self_collide>
        <sensor name='head_hokuyo_sensor' type='gpu_ray'>
          <visualize>0</visualize>
          <update_rate>40</update_rate>
          <ray>
            <scan>
              <horizontal>
                <samples>1081</samples>
                <resolution>1</resolution>
                <min_angle>-2.35619</min_angle>
                <max_angle>2.35619</max_angle>
              </horizontal>
            </scan>
            <range>
              <min>0.1</min>
              <max>30</max>
              <resolution>0.01</resolution>
            </range>
            <noise>
              <type>gaussian</type>
              <mean>0</mean>
              <stddev>0.01</stddev>
            </noise>
          </ray>
          <plugin name='gazebo_ros_head_hokuyo_controller' filename='libgazebo_ros_gpu_laser.so'>
            <topicName>/multisense/lidar_scan</topicName>
            <frameName>head_hokuyo_frame</frameName>
          </plugin>
          <pose frame=''>0.03 0 0.015 0 -0 0</pose>
        </sensor>
        <kinematic>0</kinematic>
      </link>
      <joint name='hokuyo_joint' type='revolute'>
        <child>hokuyo_link</child>
        <parent>head</parent>
        <axis>
          <xyz>1 0 0</xyz>
          <limit>
            <lower>-1e+16</lower>
            <upper>1e+16</upper>
          </limit>
          <dynamics>
            <damping>0.01</damping>
            <friction>0</friction>
            <spring_reference>0</spring_reference>
            <spring_stiffness>0</spring_stiffness>
          </dynamics>
          <use_parent_model_frame>1</use_parent_model_frame>
        </axis>
        <physics>
          <ode>
            <implicit_spring_damper>1</implicit_spring_damper>
            <cfm_damping>1</cfm_damping>
            <limit>
              <cfm>0</cfm>
              <erp>0.2</erp>
            </limit>
          </ode>
        </physics>
      </joint>
      <link name='r_clav'>
        <pose frame=''>0.1281 -0.2256 0.6896 0 -0 0</pose>
        <inertial>
          <pose frame=''>0 0 -0.084 0 -0 0</pose>
          <mass>4.466</mass>
          <inertia>
            <ixx>0.011</ixx>
            <ixy>0</ixy>
            <ixz>0</ixz>
            <iyy>0.009</iyy>
            <iyz>0.004</iyz>
            <izz>0.004</izz>
          </inertia>
        </inertial>
        <collision name='r_clav_collision'>
          <pose frame=''>0 -0.11 -0.248 -2.65359e-06 1.57079 -2.65359e-06</pose>
          <geometry>
            <cylinder>
              <length>0.1525</length>
              <radius>0.0555</radius>
            </cylinder>
          </geometry>
          <surface>
            <contact>
              <ode/>
            </contact>
            <friction>
              <ode>
                <mu>0.9</mu>
                <mu2>0.9</mu2>
              </ode>
            </friction>
            <bounce/>
          </surface>
          <max_contacts>10</max_contacts>
        </collision>
        <collision name='r_clav_collision_r_clav_1'>
          <pose frame=''>0.005 -0.015 -0.08 0 -0 0</pose>
          <geometry>
            <cylinder>
              <length>0.26</length>
              <radius>0.067</radius>
            </cylinder>
          </geometry>
          <surface>
            <contact>
              <ode/>
            </contact>
            <friction>
              <ode>
                <mu>0.9</mu>
                <mu2>0.9</mu2>
              </ode>
            </friction>
            <bounce/>
          </surface>
          <max_contacts>10</max_contacts>
        </collision>
        <collision name='r_clav_collision_r_clav_2'>
          <pose frame=''>0.004 -0.064 -0.247 1.05 -0 0</pose>
          <geometry>
            <box>
              <size>0.1 0.07 0.072</size>
            </box>
          </geometry>
          <surface>
            <contact>
              <ode/>
            </contact>
            <friction>
              <ode>
                <mu>0.9</mu>
                <mu2>0.9</mu2>
              </ode>
            </friction>
            <bounce/>
          </surface>
          <max_contacts>10</max_contacts>
        </collision>
        <visual name='r_clav_visual'>
          <pose frame=''>0 0 0 0 -0 0</pose>
          <geometry>
            <mesh>
              <scale>1 1 1</scale>
              <uri>model://atlas_description/meshes_unplugged/r_clav.dae</uri>
            </mesh>
          </geometry>
        </visual>
        <gravity>1</gravity>
        <velocity_decay/>
        <self_collide>0</self_collide>
        <kinematic>0</kinematic>
      </link>
      <joint name='r_arm_shz' type='revolute'>
        <child>r_clav</child>
        <parent>utorso</parent>
        <axis>
          <xyz>0 0 1</xyz>
          <limit>
            <lower>-0.785398</lower>
            <upper>1.5708</upper>
            <effort>87</effort>
            <velocity>12</velocity>
          </limit>
          <dynamics>
            <damping>0.1</damping>
            <friction>0</friction>
            <spring_reference>0</spring_reference>
            <spring_stiffness>0</spring_stiffness>
          </dynamics>
          <use_parent_model_frame>1</use_parent_model_frame>
        </axis>
        <physics>
          <ode>
            <implicit_spring_damper>1</implicit_spring_damper>
            <cfm_damping>1</cfm_damping>
            <limit>
              <cfm>0</cfm>
              <erp>0.2</erp>
            </limit>
          </ode>
        </physics>
      </joint>
      <link name='r_scap'>
        <pose frame=''>0.1281 -0.3356 0.4446 0 -0 0</pose>
        <inertial>
          <pose frame=''>0 0 0 0 -0 0</pose>
          <mass>3.899</mass>
          <inertia>
            <ixx>0.00319</ixx>
            <ixy>0</ixy>
            <ixz>0</ixz>
            <iyy>0.00583</iyy>
            <iyz>0</iyz>
            <izz>0.00583</izz>
          </inertia>
        </inertial>
        <collision name='r_scap_collision'>
          <pose frame=''>-0.005 -0.115 -0.014 1.5708 -0 0</pose>
          <geometry>
            <cylinder>
              <length>0.105</length>
              <radius>0.057</radius>
            </cylinder>
          </geometry>
          <surface>
            <contact>
              <ode/>
            </contact>
            <friction>
              <ode>
                <mu>0.9</mu>
                <mu2>0.9</mu2>
              </ode>
            </friction>
            <bounce/>
          </surface>
          <max_contacts>10</max_contacts>
        </collision>
        <collision name='r_scap_collision_r_scap_1'>
          <pose frame=''>-0.005 -0.075 -0.015 0 -0 0</pose>
          <geometry>
            <box>
              <size>0.16 0.17 0.08</size>
            </box>
          </geometry>
          <surface>
            <contact>
              <ode/>
            </contact>
            <friction>
              <ode>
                <mu>0.9</mu>
                <mu2>0.9</mu2>
              </ode>
            </friction>
            <bounce/>
          </surface>
          <max_contacts>10</max_contacts>
        </collision>
        <collision name='r_scap_collision_r_scap_2'>
          <pose frame=''>0.076 -0.0615 0.0128 2.25 -0 0</pose>
          <geometry>
            <box>
              <size>0.02 0.029 0.018</size>
            </box>
          </geometry>
          <surface>
            <contact>
              <ode/>
            </contact>
            <friction>
              <ode>
                <mu>0.9</mu>
                <mu2>0.9</mu2>
              </ode>
            </friction>
            <bounce/>
          </surface>
          <max_contacts>10</max_contacts>
        </collision>
        <collision name='r_scap_collision_r_scap_3'>
          <pose frame=''>-0.075 0.015 0.019 1 -0 0</pose>
          <geometry>
            <box>
              <size>0.028 0.09 0.05</size>
            </box>
          </geometry>
          <surface>
            <contact>
              <ode/>
            </contact>
            <friction>
              <ode>
                <mu>0.9</mu>
                <mu2>0.9</mu2>
              </ode>
            </friction>
            <bounce/>
          </surface>
          <max_contacts>10</max_contacts>
        </collision>
        <visual name='r_scap_visual'>
          <pose frame=''>0 0 0 0 -0 0</pose>
          <geometry>
            <mesh>
              <scale>1 1 1</scale>
              <uri>model://atlas_description/meshes_unplugged/r_scap.dae</uri>
            </mesh>
          </geometry>
        </visual>
        <gravity>1</gravity>
        <velocity_decay/>
        <self_collide>0</self_collide>
        <kinematic>0</kinematic>
      </link>
      <joint name='r_arm_shx' type='revolute'>
        <child>r_scap</child>
        <parent>r_clav</parent>
        <axis>
          <xyz>1 0 0</xyz>
          <limit>
            <lower>-1.5708</lower>
            <upper>1.5708</upper>
            <effort>99</effort>
            <velocity>12</velocity>
          </limit>
          <dynamics>
            <damping>0.1</damping>
            <friction>0</friction>
            <spring_reference>0</spring_reference>
            <spring_stiffness>0</spring_stiffness>
          </dynamics>
          <use_parent_model_frame>1</use_parent_model_frame>
        </axis>
        <physics>
          <ode>
            <implicit_spring_damper>1</implicit_spring_damper>
            <cfm_damping>1</cfm_damping>
            <limit>
              <cfm>0</cfm>
              <erp>0.2</erp>
            </limit>
          </ode>
        </physics>
      </joint>
      <link name='r_uarm'>
        <pose frame=''>0.1281 -0.5226 0.4286 0 -0 0</pose>
        <inertial>
          <pose frame=''>0 0.065 0 0 -0 0</pose>
          <mass>4.386</mass>
          <inertia>
            <ixx>0.00656</ixx>
            <ixy>0</ixy>
            <ixz>0</ixz>
            <iyy>0.00358</iyy>
            <iyz>0</iyz>
            <izz>0.00656</izz>
          </inertia>
        </inertial>
        <collision name='r_uarm_collision'>
          <pose frame=''>0 -0.035 -0.005 1.5708 -0 0</pose>
          <geometry>
            <cylinder>
              <length>0.11</length>
              <radius>0.065</radius>
            </cylinder>
          </geometry>
          <surface>
            <contact>
              <ode/>
            </contact>
            <friction>
              <ode>
                <mu>0.9</mu>
                <mu2>0.9</mu2>
              </ode>
            </friction>
            <bounce/>
          </surface>
          <max_contacts>10</max_contacts>
        </collision>
        <collision name='r_uarm_collision_r_uarm_1'>
          <pose frame=''>-0.01 -0.043 0.002 -2.65359e-06 1.57079 -2.65359e-06</pose>
          <geometry>
            <box>
              <size>0.05 0.07 0.15</size>
            </box>
          </geometry>
          <surface>
            <contact>
              <ode/>
            </contact>
            <friction>
              <ode>
                <mu>0.9</mu>
                <mu2>0.9</mu2>
              </ode>
            </friction>
            <bounce/>
          </surface>
          <max_contacts>10</max_contacts>
        </collision>
        <visual name='r_uarm_visual'>
          <pose frame=''>0 0 0 0 -0 0</pose>
          <geometry>
            <mesh>
              <scale>1 1 1</scale>
              <uri>model://atlas_description/meshes_unplugged/r_uarm.dae</uri>
            </mesh>
          </geometry>
        </visual>
        <gravity>1</gravity>
        <velocity_decay/>
        <self_collide>0</self_collide>
        <kinematic>0</kinematic>
      </link>
      <joint name='r_arm_ely' type='revolute'>
        <child>r_uarm</child>
        <parent>r_scap</parent>
        <axis>
          <xyz>0 1 0</xyz>
          <limit>
            <lower>0</lower>
            <upper>3.14159</upper>
            <effort>63</effort>
            <velocity>12</velocity>
          </limit>
          <dynamics>
            <damping>0.1</damping>
            <friction>0</friction>
            <spring_reference>0</spring_reference>
            <spring_stiffness>0</spring_stiffness>
          </dynamics>
          <use_parent_model_frame>1</use_parent_model_frame>
        </axis>
        <physics>
          <ode>
            <implicit_spring_damper>1</implicit_spring_damper>
            <cfm_damping>1</cfm_damping>
            <limit>
              <cfm>0</cfm>
              <erp>0.2</erp>
            </limit>
          </ode>
        </physics>
      </joint>
      <link name='r_larm'>
        <pose frame=''>0.1281 -0.6416 0.4378 0 -0 0</pose>
        <inertial>
          <pose frame=''>0 0 0 0 -0 0</pose>
          <mass>3.248</mass>
          <inertia>
            <ixx>0.00265</ixx>
            <ixy>0</ixy>
            <ixz>0</ixz>
            <iyy>0.00446</iyy>
            <iyz>0</iyz>
            <izz>0.00446</izz>
          </inertia>
        </inertial>
        <collision name='r_larm_collision'>
          <pose frame=''>0 -0.075 -0.01 -1.5708 0 0</pose>
          <geometry>
            <cylinder>
              <length>0.04</length>
              <radius>0.051</radius>
            </cylinder>
          </geometry>
          <surface>
            <contact>
              <ode/>
            </contact>
            <friction>
              <ode>
                <mu>0.9</mu>
                <mu2>0.9</mu2>
              </ode>
            </friction>
            <bounce/>
          </surface>
          <max_contacts>10</max_contacts>
        </collision>
        <collision name='r_larm_collision_r_larm_1'>
          <pose frame=''>-0.012 0 0.0025 -2.65359e-06 1.57079 -2.65359e-06</pose>
          <geometry>
            <cylinder>
              <length>0.147</length>
              <radius>0.045</radius>
            </cylinder>
          </geometry>
          <surface>
            <contact>
              <ode/>
            </contact>
            <friction>
              <ode>
                <mu>0.9</mu>
                <mu2>0.9</mu2>
              </ode>
            </friction>
            <bounce/>
          </surface>
          <max_contacts>10</max_contacts>
        </collision>
        <collision name='r_larm_collision_r_larm_2'>
          <pose frame=''>-0.07 -0.077 -0.015 0 -0 0</pose>
          <geometry>
            <box>
              <size>0.025 0.155 0.07</size>
            </box>
          </geometry>
          <surface>
            <contact>
              <ode/>
            </contact>
            <friction>
              <ode>
                <mu>0.9</mu>
                <mu2>0.9</mu2>
              </ode>
            </friction>
            <bounce/>
          </surface>
          <max_contacts>10</max_contacts>
        </collision>
        <collision name='r_larm_collision_r_larm_3'>
          <pose frame=''>0.05 -0.067 -0.009 0 -0 0</pose>
          <geometry>
            <box>
              <size>0.025 0.06 0.06</size>
            </box>
          </geometry>
          <surface>
            <contact>
              <ode/>
            </contact>
            <friction>
              <ode>
                <mu>0.9</mu>
                <mu2>0.9</mu2>
              </ode>
            </friction>
            <bounce/>
          </surface>
          <max_contacts>10</max_contacts>
        </collision>
        <collision name='r_larm_collision_r_larm_4'>
          <pose frame=''>-0.032 -0.071 -0.06 0 -0 0</pose>
          <geometry>
            <box>
              <size>0.04 0.115 0.05</size>
            </box>
          </geometry>
          <surface>
            <contact>
              <ode/>
            </contact>
            <friction>
              <ode>
                <mu>0.9</mu>
                <mu2>0.9</mu2>
              </ode>
            </friction>
            <bounce/>
          </surface>
          <max_contacts>10</max_contacts>
        </collision>
        <collision name='r_larm_collision_r_larm_5'>
          <pose frame=''>0.03 0.01 -0.05 0 -0 0</pose>
          <geometry>
            <box>
              <size>0.045 0.055 0.023</size>
            </box>
          </geometry>
          <surface>
            <contact>
              <ode/>
            </contact>
            <friction>
              <ode>
                <mu>0.9</mu>
                <mu2>0.9</mu2>
              </ode>
            </friction>
            <bounce/>
          </surface>
          <max_contacts>10</max_contacts>
        </collision>
        <visual name='r_larm_visual'>
          <pose frame=''>0 0 0 0 -0 0</pose>
          <geometry>
            <mesh>
              <scale>1 1 1</scale>
              <uri>model://atlas_description/meshes_unplugged/r_larm.dae</uri>
            </mesh>
          </geometry>
        </visual>
        <gravity>1</gravity>
        <velocity_decay/>
        <self_collide>0</self_collide>
        <kinematic>0</kinematic>
      </link>
      <joint name='r_arm_elx' type='revolute'>
        <child>r_larm</child>
        <parent>r_uarm</parent>
        <axis>
          <xyz>1 0 0</xyz>
          <limit>
            <lower>-2.35619</lower>
            <upper>0</upper>
            <effort>112</effort>
            <velocity>12</velocity>
          </limit>
          <dynamics>
            <damping>0.1</damping>
            <friction>0</friction>
            <spring_reference>0</spring_reference>
            <spring_stiffness>0</spring_stiffness>
          </dynamics>
          <use_parent_model_frame>1</use_parent_model_frame>
        </axis>
        <physics>
          <ode>
            <implicit_spring_damper>1</implicit_spring_damper>
            <cfm_damping>1</cfm_damping>
            <limit>
              <cfm>0</cfm>
              <erp>0.2</erp>
            </limit>
          </ode>
        </physics>
      </joint>
      <link name='r_ufarm'>
        <pose frame=''>0.1281 -0.94115 0.42859 0 -0 0</pose>
        <inertial>
          <pose frame=''>0.00015 0.08296 0.00037 0 -0 0</pose>
          <mass>2.4798</mass>
          <inertia>
            <ixx>0.012731</ixx>
            <ixy>0</ixy>
            <ixz>0</ixz>
            <iyy>0.002857</iyy>
            <iyz>0</iyz>
            <izz>0.011948</izz>
          </inertia>
        </inertial>
        <collision name='r_ufarm_collision'>
          <pose frame=''>0 0.15 0 1.57 -0 0</pose>
          <geometry>
            <cylinder>
              <length>0.1</length>
              <radius>0.053</radius>
            </cylinder>
          </geometry>
          <surface>
            <contact>
              <ode/>
            </contact>
            <friction>
              <ode>
                <mu>0.9</mu>
                <mu2>0.9</mu2>
              </ode>
            </friction>
            <bounce/>
          </surface>
          <max_contacts>10</max_contacts>
        </collision>
        <collision name='r_ufarm_collision_r_ufarm_1'>
          <pose frame=''>-0.001 0.07 0 -2.65359e-06 1.57079 -2.65359e-06</pose>
          <geometry>
            <box>
              <size>0.08 0.09 0.11</size>
            </box>
          </geometry>
          <surface>
            <contact>
              <ode/>
            </contact>
            <friction>
              <ode>
                <mu>0.9</mu>
                <mu2>0.9</mu2>
              </ode>
            </friction>
            <bounce/>
          </surface>
          <max_contacts>10</max_contacts>
        </collision>
        <collision name='r_ufarm_collision_r_ufarm_2'>
          <pose frame=''>0 0.005 0 0 1.57 0</pose>
          <geometry>
            <cylinder>
              <length>0.125</length>
              <radius>0.04</radius>
            </cylinder>
          </geometry>
          <surface>
            <contact>
              <ode/>
            </contact>
            <friction>
              <ode>
                <mu>0.9</mu>
                <mu2>0.9</mu2>
              </ode>
            </friction>
            <bounce/>
          </surface>
          <max_contacts>10</max_contacts>
        </collision>
        <visual name='r_ufarm_visual'>
          <pose frame=''>0 0 0 0 -0 0</pose>
          <geometry>
            <mesh>
              <scale>1 1 1</scale>
              <uri>model://atlas_description/meshes_unplugged/r_farm.dae</uri>
            </mesh>
          </geometry>
        </visual>
        <gravity>1</gravity>
        <velocity_decay/>
        <self_collide>0</self_collide>
        <kinematic>0</kinematic>
      </link>
      <joint name='r_arm_wry' type='revolute'>
        <child>r_ufarm</child>
        <parent>r_larm</parent>
        <axis>
          <xyz>0 1 0</xyz>
          <limit>
            <lower>-3.011</lower>
            <upper>3.011</upper>
            <effort>25</effort>
            <velocity>10</velocity>
          </limit>
          <dynamics>
            <damping>0.1</damping>
            <friction>0</friction>
            <spring_reference>0</spring_reference>
            <spring_stiffness>0</spring_stiffness>
          </dynamics>
          <use_parent_model_frame>1</use_parent_model_frame>
        </axis>
        <physics>
          <ode>
            <implicit_spring_damper>1</implicit_spring_damper>
            <cfm_damping>1</cfm_damping>
            <limit>
              <cfm>0</cfm>
              <erp>0.2</erp>
            </limit>
          </ode>
        </physics>
      </joint>
      <link name='r_lfarm'>
        <pose frame=''>0.1281 -0.94115 0.42859 0 -0 0</pose>
        <inertial>
          <pose frame=''>0.00017 -0.02515 0.00163 0 -0 0</pose>
          <mass>0.648</mass>
          <inertia>
            <ixx>0.000764</ixx>
            <ixy>0</ixy>
            <ixz>0</ixz>
            <iyy>0.000429</iyy>
            <iyz>0</iyz>
            <izz>0.000825</izz>
          </inertia>
        </inertial>
        <collision name='r_lfarm_collision'>
          <pose frame=''>0 -0.104 0 1.5708 -0 0</pose>
          <geometry>
            <cylinder>
              <length>0.02</length>
              <radius>0.031</radius>
            </cylinder>
          </geometry>
          <surface>
            <contact>
              <ode/>
            </contact>
            <friction>
              <ode>
                <mu>0.9</mu>
                <mu2>0.9</mu2>
              </ode>
            </friction>
            <bounce/>
          </surface>
          <max_contacts>10</max_contacts>
        </collision>
        <collision name='r_lfarm_collision_r_lfarm_1'>
          <pose frame=''>0 -0.087 0 1.5708 -0 0</pose>
          <geometry>
            <cylinder>
              <length>0.015</length>
              <radius>0.045</radius>
            </cylinder>
          </geometry>
          <surface>
            <contact>
              <ode/>
            </contact>
            <friction>
              <ode>
                <mu>0.9</mu>
                <mu2>0.9</mu2>
              </ode>
            </friction>
            <bounce/>
          </surface>
          <max_contacts>10</max_contacts>
        </collision>
        <collision name='r_lfarm_collision_r_lfarm_2'>
          <pose frame=''>0 -0.075 0 1.5708 -0 0</pose>
          <geometry>
            <cylinder>
              <length>0.015</length>
              <radius>0.052</radius>
            </cylinder>
          </geometry>
          <surface>
            <contact>
              <ode/>
            </contact>
            <friction>
              <ode>
                <mu>0.9</mu>
                <mu2>0.9</mu2>
              </ode>
            </friction>
            <bounce/>
          </surface>
          <max_contacts>10</max_contacts>
        </collision>
        <collision name='r_lfarm_collision_r_lfarm_3'>
          <pose frame=''>0 -0.052 0 1.5708 -0 0</pose>
          <geometry>
            <cylinder>
              <length>0.027</length>
              <radius>0.043</radius>
            </cylinder>
          </geometry>
          <surface>
            <contact>
              <ode/>
            </contact>
            <friction>
              <ode>
                <mu>0.9</mu>
                <mu2>0.9</mu2>
              </ode>
            </friction>
            <bounce/>
          </surface>
          <max_contacts>10</max_contacts>
        </collision>
        <visual name='r_lfarm_visual'>
          <pose frame=''>0 0 0 3.14159 -2.06823e-13 3.14159</pose>
          <geometry>
            <mesh>
              <scale>1 1 1</scale>
              <uri>model://atlas_description/meshes_unplugged/r_hand.dae</uri>
            </mesh>
          </geometry>
        </visual>
        <gravity>1</gravity>
        <velocity_decay/>
        <self_collide>0</self_collide>
        <kinematic>0</kinematic>
      </link>
      <joint name='r_arm_wrx' type='revolute'>
        <child>r_lfarm</child>
        <parent>r_ufarm</parent>
        <axis>
          <xyz>1 0 0</xyz>
          <limit>
            <lower>-1.7628</lower>
            <upper>1.7628</upper>
            <effort>25</effort>
            <velocity>10</velocity>
          </limit>
          <dynamics>
            <damping>0.1</damping>
            <friction>0</friction>
            <spring_reference>0</spring_reference>
            <spring_stiffness>0</spring_stiffness>
          </dynamics>
          <use_parent_model_frame>1</use_parent_model_frame>
        </axis>
        <physics>
          <provide_feedback>1</provide_feedback>
          <ode>
            <provide_feedback>1</provide_feedback>
            <limit>
              <cfm>0</cfm>
              <erp>0.2</erp>
            </limit>
            <implicit_spring_damper>1</implicit_spring_damper>
            <cfm_damping>1</cfm_damping>
          </ode>
        </physics>
      </joint>
      <link name='r_hand'>
        <pose frame=''>0.1281 -0.94115 0.42859 0 -0 0</pose>
        <inertial>
          <pose frame=''>0.00016 -0.08159 2e-05 0 -0 0</pose>
          <mass>0.5839</mass>
          <inertia>
            <ixx>0.000388</ixx>
            <ixy>0</ixy>
            <ixz>0</ixz>
            <iyy>0.000477</iyy>
            <iyz>0</iyz>
            <izz>0.000379</izz>
          </inertia>
        </inertial>
        <gravity>1</gravity>
        <velocity_decay/>
        <self_collide>0</self_collide>
        <kinematic>0</kinematic>
      </link>
      <joint name='r_arm_wry2' type='revolute'>
        <child>r_hand</child>
        <parent>r_lfarm</parent>
        <axis>
          <xyz>0 1 0</xyz>
          <limit>
            <lower>-2.9671</lower>
            <upper>2.9671</upper>
            <effort>25</effort>
            <velocity>10</velocity>
          </limit>
          <dynamics>
            <damping>0.1</damping>
            <friction>0</friction>
            <spring_reference>0</spring_reference>
            <spring_stiffness>0</spring_stiffness>
          </dynamics>
          <use_parent_model_frame>1</use_parent_model_frame>
        </axis>
        <physics>
          <ode>
            <implicit_spring_damper>1</implicit_spring_damper>
            <cfm_damping>1</cfm_damping>
            <limit>
              <cfm>0</cfm>
              <erp>0.2</erp>
            </limit>
          </ode>
        </physics>
      </joint>
      <link name='l_uglut'>
        <pose frame=''>0 0.089 0 0 -0 0</pose>
        <inertial>
          <pose frame=''>0.00529262 -0.00344732 0.00313046 0 -0 0</pose>
          <mass>1.959</mass>
          <inertia>
            <ixx>0.00074276</ixx>
            <ixy>-3.79607e-08</ixy>
            <ixz>-2.79549e-05</ixz>
            <iyy>0.000688179</iyy>
            <iyz>-3.2735e-08</iyz>
            <izz>0.00041242</izz>
          </inertia>
        </inertial>
        <collision name='l_uglut_collision'>
          <pose frame=''>0.01 0.005 0 0.52539 -0 0</pose>
          <geometry>
            <box>
              <size>0.05 0.1 0.1</size>
            </box>
          </geometry>
          <surface>
            <contact>
              <ode/>
            </contact>
            <friction>
              <ode>
                <mu>0.9</mu>
                <mu2>0.9</mu2>
              </ode>
            </friction>
            <bounce/>
          </surface>
          <max_contacts>10</max_contacts>
        </collision>
        <collision name='l_uglut_collision_l_uglut_1'>
          <pose frame=''>0 0 0 0 -0 0</pose>
          <geometry>
            <cylinder>
              <length>0.080842</length>
              <radius>0.019841</radius>
            </cylinder>
          </geometry>
          <surface>
            <contact>
              <ode/>
            </contact>
            <friction>
              <ode>
                <mu>0.9</mu>
                <mu2>0.9</mu2>
              </ode>
            </friction>
            <bounce/>
          </surface>
          <max_contacts>10</max_contacts>
        </collision>
        <visual name='l_uglut_visual'>
          <pose frame=''>0 0 0 0 -0 0</pose>
          <geometry>
            <mesh>
              <scale>1 1 1</scale>
              <uri>model://atlas_description/meshes_unplugged/l_uglut.dae</uri>
            </mesh>
          </geometry>
        </visual>
        <gravity>1</gravity>
        <velocity_decay/>
        <self_collide>0</self_collide>
        <kinematic>0</kinematic>
      </link>
      <joint name='l_leg_hpz' type='revolute'>
        <child>l_uglut</child>
        <parent>pelvis</parent>
        <axis>
          <xyz>0 0 1</xyz>
          <limit>
            <lower>-0.174358</lower>
            <upper>0.786794</upper>
            <effort>275</effort>
            <velocity>12</velocity>
          </limit>
          <dynamics>
            <damping>0.1</damping>
            <friction>0</friction>
            <spring_reference>0</spring_reference>
            <spring_stiffness>0</spring_stiffness>
          </dynamics>
          <use_parent_model_frame>1</use_parent_model_frame>
        </axis>
        <physics>
          <ode>
            <implicit_spring_damper>1</implicit_spring_damper>
            <cfm_damping>1</cfm_damping>
            <limit>
              <cfm>0</cfm>
              <erp>0.2</erp>
            </limit>
          </ode>
        </physics>
      </joint>
      <link name='l_lglut'>
        <pose frame=''>0 0.089 0 0 -0 0</pose>
        <inertial>
          <pose frame=''>0.0133341 0.0170484 -0.0312052 0 -0 0</pose>
          <mass>0.898</mass>
          <inertia>
            <ixx>0.000691326</ixx>
            <ixy>-2.24344e-05</ixy>
            <ixz>2.50508e-06</ixz>
            <iyy>0.00126856</iyy>
            <iyz>0.000137862</iyz>
            <izz>0.00106487</izz>
          </inertia>
        </inertial>
        <collision name='l_lglut_collision'>
          <pose frame=''>0.015 0.026 -0.028 0 -0 0</pose>
          <geometry>
            <box>
              <size>0.125 0.05 0.08</size>
            </box>
          </geometry>
          <surface>
            <contact>
              <ode/>
            </contact>
            <friction>
              <ode>
                <mu>0.9</mu>
                <mu2>0.9</mu2>
              </ode>
            </friction>
            <bounce/>
          </surface>
          <max_contacts>10</max_contacts>
        </collision>
        <collision name='l_lglut_collision_l_lglut_1'>
          <pose frame=''>0.05 0.027488 -0.067 1.5708 -0 0</pose>
          <geometry>
            <cylinder>
              <length>0.060306</length>
              <radius>0.0200969</radius>
            </cylinder>
          </geometry>
          <surface>
            <contact>
              <ode/>
            </contact>
            <friction>
              <ode>
                <mu>0.9</mu>
                <mu2>0.9</mu2>
              </ode>
            </friction>
            <bounce/>
          </surface>
          <max_contacts>10</max_contacts>
        </collision>
        <collision name='l_lglut_collision_l_lglut_2'>
          <pose frame=''>0.0115 0 0 -2.65359e-06 1.57079 -2.65359e-06</pose>
          <geometry>
            <cylinder>
              <length>0.144</length>
              <radius>0.02</radius>
            </cylinder>
          </geometry>
          <surface>
            <contact>
              <ode/>
            </contact>
            <friction>
              <ode>
                <mu>0.9</mu>
                <mu2>0.9</mu2>
              </ode>
            </friction>
            <bounce/>
          </surface>
          <max_contacts>10</max_contacts>
        </collision>
        <collision name='l_lglut_collision_l_lglut_3'>
          <pose frame=''>0.01 0.02 0.01 0 -0 0</pose>
          <geometry>
            <box>
              <size>0.0975 0.069 0.103</size>
            </box>
          </geometry>
          <surface>
            <contact>
              <ode/>
            </contact>
            <friction>
              <ode>
                <mu>0.9</mu>
                <mu2>0.9</mu2>
              </ode>
            </friction>
            <bounce/>
          </surface>
          <max_contacts>10</max_contacts>
        </collision>
        <visual name='l_lglut_visual'>
          <pose frame=''>0 0 0 0 -0 0</pose>
          <geometry>
            <mesh>
              <scale>1 1 1</scale>
              <uri>model://atlas_description/meshes_unplugged/l_lglut.dae</uri>
            </mesh>
          </geometry>
        </visual>
        <gravity>1</gravity>
        <velocity_decay/>
        <self_collide>0</self_collide>
        <kinematic>0</kinematic>
      </link>
      <joint name='l_leg_hpx' type='revolute'>
        <child>l_lglut</child>
        <parent>l_uglut</parent>
        <axis>
          <xyz>1 0 0</xyz>
          <limit>
            <lower>-0.523599</lower>
            <upper>0.523599</upper>
            <effort>530</effort>
            <velocity>12</velocity>
          </limit>
          <dynamics>
            <damping>0.1</damping>
            <friction>0</friction>
            <spring_reference>0</spring_reference>
            <spring_stiffness>0</spring_stiffness>
          </dynamics>
          <use_parent_model_frame>1</use_parent_model_frame>
        </axis>
        <physics>
          <ode>
            <implicit_spring_damper>1</implicit_spring_damper>
            <cfm_damping>1</cfm_damping>
            <limit>
              <cfm>0</cfm>
              <erp>0.2</erp>
            </limit>
          </ode>
        </physics>
      </joint>
      <link name='l_uleg'>
        <pose frame=''>0.05 0.1115 -0.066 0 -0 0</pose>
        <inertial>
          <pose frame=''>0 0 -0.21 0 -0 0</pose>
          <mass>8.204</mass>
          <inertia>
            <ixx>0.09</ixx>
            <ixy>0</ixy>
            <ixz>0</ixz>
            <iyy>0.09</iyy>
            <iyz>0</iyz>
            <izz>0.02</izz>
          </inertia>
        </inertial>
        <collision name='l_uleg_collision'>
          <pose frame=''>-0.0199 0.00585 -0.122 0 -0 0</pose>
          <geometry>
            <cylinder>
              <length>0.15</length>
              <radius>0.09</radius>
            </cylinder>
          </geometry>
          <surface>
            <contact>
              <ode/>
            </contact>
            <friction>
              <ode>
                <mu>0.9</mu>
                <mu2>0.9</mu2>
              </ode>
            </friction>
            <bounce/>
          </surface>
          <max_contacts>10</max_contacts>
        </collision>
        <collision name='l_uleg_collision_l_uleg_1'>
          <pose frame=''>-0.032 -0.005 -0.224 0 -0.3 0</pose>
          <geometry>
            <cylinder>
              <length>0.15</length>
              <radius>0.07</radius>
            </cylinder>
          </geometry>
          <surface>
            <contact>
              <ode/>
            </contact>
            <friction>
              <ode>
                <mu>0.9</mu>
                <mu2>0.9</mu2>
              </ode>
            </friction>
            <bounce/>
          </surface>
          <max_contacts>10</max_contacts>
        </collision>
        <collision name='l_uleg_collision_l_uleg_2'>
          <pose frame=''>0.003 0.015 -0.254 -0.15 0.13 6.99794e-18</pose>
          <geometry>
            <cylinder>
              <length>0.15</length>
              <radius>0.05</radius>
            </cylinder>
          </geometry>
          <surface>
            <contact>
              <ode/>
            </contact>
            <friction>
              <ode>
                <mu>0.9</mu>
                <mu2>0.9</mu2>
              </ode>
            </friction>
            <bounce/>
          </surface>
          <max_contacts>10</max_contacts>
        </collision>
        <collision name='l_uleg_collision_l_uleg_3'>
          <pose frame=''>-0.007 -0.053 -0.052 0 -0 0</pose>
          <geometry>
            <box>
              <size>0.07 0.038 0.15</size>
            </box>
          </geometry>
          <surface>
            <contact>
              <ode/>
            </contact>
            <friction>
              <ode>
                <mu>0.9</mu>
                <mu2>0.9</mu2>
              </ode>
            </friction>
            <bounce/>
          </surface>
          <max_contacts>10</max_contacts>
        </collision>
        <collision name='l_uleg_collision_l_uleg_4'>
          <pose frame=''>-0.017 0.0595 -0.049 0 -0 0</pose>
          <geometry>
            <box>
              <size>0.07 0.038 0.14</size>
            </box>
          </geometry>
          <surface>
            <contact>
              <ode/>
            </contact>
            <friction>
              <ode>
                <mu>0.9</mu>
                <mu2>0.9</mu2>
              </ode>
            </friction>
            <bounce/>
          </surface>
          <max_contacts>10</max_contacts>
        </collision>
        <visual name='l_uleg_visual'>
          <pose frame=''>0 0 0 0 -0 0</pose>
          <geometry>
            <mesh>
              <scale>1 1 1</scale>
              <uri>model://atlas_description/meshes_unplugged/l_uleg.dae</uri>
            </mesh>
          </geometry>
        </visual>
        <gravity>1</gravity>
        <velocity_decay/>
        <self_collide>0</self_collide>
        <kinematic>0</kinematic>
      </link>
      <joint name='l_leg_hpy' type='revolute'>
        <child>l_uleg</child>
        <parent>l_lglut</parent>
        <axis>
          <xyz>0 1 0</xyz>
          <limit>
            <lower>-1.61234</lower>
            <upper>0.65764</upper>
            <effort>840</effort>
            <velocity>12</velocity>
          </limit>
          <dynamics>
            <damping>0.1</damping>
            <friction>0</friction>
            <spring_reference>0</spring_reference>
            <spring_stiffness>0</spring_stiffness>
          </dynamics>
          <use_parent_model_frame>1</use_parent_model_frame>
        </axis>
        <physics>
          <ode>
            <implicit_spring_damper>1</implicit_spring_damper>
            <cfm_damping>1</cfm_damping>
            <limit>
              <cfm>0</cfm>
              <erp>0.2</erp>
            </limit>
          </ode>
        </physics>
      </joint>
      <link name='l_lleg'>
        <pose frame=''>0 0.1115 -0.44 0 -0 0</pose>
        <inertial>
          <pose frame=''>0.001 0 -0.187 0 -0 0</pose>
          <mass>4.515</mass>
          <inertia>
            <ixx>0.077</ixx>
            <ixy>0</ixy>
            <ixz>-0.003</ixz>
            <iyy>0.076</iyy>
            <iyz>0</iyz>
            <izz>0.01</izz>
          </inertia>
        </inertial>
        <collision name='l_lleg_collision'>
          <pose frame=''>0.02 0.00295 -0.182 0 0.1 0</pose>
          <geometry>
            <cylinder>
              <length>0.4</length>
              <radius>0.07</radius>
            </cylinder>
          </geometry>
          <surface>
            <contact>
              <ode/>
            </contact>
            <friction>
              <ode>
                <mu>0.9</mu>
                <mu2>0.9</mu2>
              </ode>
            </friction>
            <bounce/>
          </surface>
          <max_contacts>10</max_contacts>
        </collision>
        <visual name='l_lleg_visual'>
          <pose frame=''>0 0 0 0 -0 0</pose>
          <geometry>
            <mesh>
              <scale>1 1 1</scale>
              <uri>model://atlas_description/meshes_unplugged/l_lleg.dae</uri>
            </mesh>
          </geometry>
        </visual>
        <gravity>1</gravity>
        <velocity_decay/>
        <self_collide>0</self_collide>
        <kinematic>0</kinematic>
      </link>
      <joint name='l_leg_kny' type='revolute'>
        <child>l_lleg</child>
        <parent>l_uleg</parent>
        <axis>
          <xyz>0 1 0</xyz>
          <limit>
            <lower>0</lower>
            <upper>2.35637</upper>
            <effort>890</effort>
            <velocity>12</velocity>
          </limit>
          <dynamics>
            <damping>0.1</damping>
            <friction>0</friction>
            <spring_reference>0</spring_reference>
            <spring_stiffness>0</spring_stiffness>
          </dynamics>
          <use_parent_model_frame>1</use_parent_model_frame>
        </axis>
        <physics>
          <ode>
            <implicit_spring_damper>1</implicit_spring_damper>
            <cfm_damping>1</cfm_damping>
            <limit>
              <cfm>0</cfm>
              <erp>0.2</erp>
            </limit>
          </ode>
        </physics>
      </joint>
      <link name='l_talus'>
        <pose frame=''>0 0.1115 -0.862 0 -0 0</pose>
        <inertial>
          <pose frame=''>0 0 0 0 -0 0</pose>
          <mass>0.125</mass>
          <inertia>
            <ixx>1.01674e-05</ixx>
            <ixy>0</ixy>
            <ixz>0</ixz>
            <iyy>8.42775e-06</iyy>
            <iyz>0</iyz>
            <izz>1.30101e-05</izz>
          </inertia>
        </inertial>
        <collision name='l_talus_collision'>
          <pose frame=''>0 0 0 -2.65359e-06 1.57079 -2.65359e-06</pose>
          <geometry>
            <cylinder>
              <length>0.029542</length>
              <radius>0.010181</radius>
            </cylinder>
          </geometry>
          <surface>
            <contact>
              <ode/>
            </contact>
            <friction>
              <ode>
                <mu>0.9</mu>
                <mu2>0.9</mu2>
              </ode>
            </friction>
            <bounce/>
          </surface>
          <max_contacts>10</max_contacts>
        </collision>
        <collision name='l_talus_collision_l_talus_1'>
          <pose frame=''>0 0 0 1.5708 -0 0</pose>
          <geometry>
            <cylinder>
              <length>0.010059</length>
              <radius>0.010348</radius>
            </cylinder>
          </geometry>
          <surface>
            <contact>
              <ode/>
            </contact>
            <friction>
              <ode>
                <mu>0.9</mu>
                <mu2>0.9</mu2>
              </ode>
            </friction>
            <bounce/>
          </surface>
          <max_contacts>10</max_contacts>
        </collision>
        <visual name='l_talus_visual'>
          <pose frame=''>0 0 0 0 -0 0</pose>
          <geometry>
            <mesh>
              <scale>1 1 1</scale>
              <uri>model://atlas_description/meshes_unplugged/l_talus.dae</uri>
            </mesh>
          </geometry>
        </visual>
        <gravity>1</gravity>
        <velocity_decay/>
        <self_collide>0</self_collide>
        <kinematic>0</kinematic>
      </link>
      <joint name='l_leg_aky' type='revolute'>
        <child>l_talus</child>
        <parent>l_lleg</parent>
        <axis>
          <xyz>0 1 0</xyz>
          <limit>
            <lower>-1</lower>
            <upper>0.7</upper>
            <effort>740</effort>
            <velocity>12</velocity>
          </limit>
          <dynamics>
            <damping>0.1</damping>
            <friction>0</friction>
            <spring_reference>0</spring_reference>
            <spring_stiffness>0</spring_stiffness>
          </dynamics>
          <use_parent_model_frame>1</use_parent_model_frame>
        </axis>
        <physics>
          <ode>
            <implicit_spring_damper>1</implicit_spring_damper>
            <cfm_damping>1</cfm_damping>
            <limit>
              <cfm>0</cfm>
              <erp>0.2</erp>
            </limit>
          </ode>
        </physics>
      </joint>
      <link name='l_foot'>
        <pose frame=''>0 0.1115 -0.862 0 -0 0</pose>
        <inertial>
          <pose frame=''>0.027 0 -0.067 0 -0 0</pose>
          <mass>2.41</mass>
          <inertia>
            <ixx>0.002</ixx>
            <ixy>0</ixy>
            <ixz>0</ixz>
            <iyy>0.007</iyy>
            <iyz>0</iyz>
            <izz>0.008</izz>
          </inertia>
        </inertial>
        <collision name='l_foot_collision'>
          <pose frame=''>0.023 0 -0.049119 0 -0 0</pose>
          <geometry>
            <box>
              <size>0.227 0.133887 0.05</size>
            </box>
          </geometry>
          <surface>
            <contact>
              <ode>
                <kp>1e+06</kp>
                <kd>100</kd>
                <max_vel>1</max_vel>
                <min_depth>0</min_depth>
              </ode>
            </contact>
            <friction>
              <ode>
                <mu>1.5</mu>
                <mu2>1.5</mu2>
                <fdir1>1 0 0</fdir1>
              </ode>
            </friction>
            <bounce/>
          </surface>
          <surface>
            <contact>
              <ode/>
            </contact>
            <friction>
              <ode/>
            </friction>
          </surface>
          <max_contacts>10</max_contacts>
        </collision>
        <collision name='l_foot_collision_l_foot_1'>
          <pose frame=''>0.1225 0 -0.0641 0 -0 0</pose>
          <geometry>
            <box>
              <size>0.1 0.08 0.02</size>
            </box>
          </geometry>
          <surface>
            <contact>
              <ode>
                <kp>1e+06</kp>
                <kd>100</kd>
                <max_vel>1</max_vel>
                <min_depth>0</min_depth>
              </ode>
            </contact>
            <friction>
              <ode>
                <mu>1.5</mu>
                <mu2>1.5</mu2>
                <fdir1>1 0 0</fdir1>
              </ode>
            </friction>
            <bounce/>
          </surface>
          <surface>
            <contact>
              <ode/>
            </contact>
            <friction>
              <ode/>
            </friction>
          </surface>
          <max_contacts>10</max_contacts>
        </collision>
        <visual name='l_foot_visual'>
          <pose frame=''>0 0 0 0 -0 0</pose>
          <geometry>
            <mesh>
              <scale>1 1 1</scale>
              <uri>model://atlas_description/meshes_unplugged/l_foot.dae</uri>
            </mesh>
          </geometry>
        </visual>
        <velocity_decay/>
        <gravity>1</gravity>
        <velocity_decay/>
        <self_collide>0</self_collide>
        <sensor name='l_foot_contact_sensor' type='contact'>
          <update_rate>1000</update_rate>
          <always_on>1</always_on>
          <contact>
            <collision>l_foot_collision</collision>
            <topic>/l_foot_contact</topic>
          </contact>
        </sensor>
        <kinematic>0</kinematic>
      </link>
      <joint name='l_leg_akx' type='revolute'>
        <child>l_foot</child>
        <parent>l_talus</parent>
        <axis>
          <xyz>1 0 0</xyz>
          <limit>
            <lower>-0.8</lower>
            <upper>0.8</upper>
            <effort>360</effort>
            <velocity>12</velocity>
          </limit>
          <dynamics>
            <damping>0.1</damping>
            <friction>0</friction>
            <spring_reference>0</spring_reference>
            <spring_stiffness>0</spring_stiffness>
          </dynamics>
          <use_parent_model_frame>1</use_parent_model_frame>
        </axis>
        <physics>
          <provide_feedback>1</provide_feedback>
          <ode>
            <provide_feedback>1</provide_feedback>
            <implicit_spring_damper>1</implicit_spring_damper>
            <cfm_damping>1</cfm_damping>
            <limit>
              <cfm>0</cfm>
              <erp>0.2</erp>
            </limit>
          </ode>
        </physics>
      </joint>
      <link name='r_uglut'>
        <pose frame=''>0 -0.089 0 0 -0 0</pose>
        <inertial>
          <pose frame=''>0.00529262 0.00344732 0.00313046 0 -0 0</pose>
          <mass>1.959</mass>
          <inertia>
            <ixx>0.00074276</ixx>
            <ixy>3.79607e-08</ixy>
            <ixz>-2.79549e-05</ixz>
            <iyy>0.000688179</iyy>
            <iyz>3.2735e-08</iyz>
            <izz>0.00041242</izz>
          </inertia>
        </inertial>
        <collision name='r_uglut_collision'>
          <pose frame=''>0.01 -0.005 0 -0.52539 0 0</pose>
          <geometry>
            <box>
              <size>0.05 0.1 0.1</size>
            </box>
          </geometry>
          <surface>
            <contact>
              <ode/>
            </contact>
            <friction>
              <ode>
                <mu>0.9</mu>
                <mu2>0.9</mu2>
              </ode>
            </friction>
            <bounce/>
          </surface>
          <max_contacts>10</max_contacts>
        </collision>
        <collision name='r_uglut_collision_r_uglut_1'>
          <pose frame=''>0 0 0 0 -0 0</pose>
          <geometry>
            <cylinder>
              <length>0.080842</length>
              <radius>0.019841</radius>
            </cylinder>
          </geometry>
          <surface>
            <contact>
              <ode/>
            </contact>
            <friction>
              <ode>
                <mu>0.9</mu>
                <mu2>0.9</mu2>
              </ode>
            </friction>
            <bounce/>
          </surface>
          <max_contacts>10</max_contacts>
        </collision>
        <visual name='r_uglut_visual'>
          <pose frame=''>0 0 0 0 -0 0</pose>
          <geometry>
            <mesh>
              <scale>1 1 1</scale>
              <uri>model://atlas_description/meshes_unplugged/r_uglut.dae</uri>
            </mesh>
          </geometry>
        </visual>
        <gravity>1</gravity>
        <velocity_decay/>
        <self_collide>0</self_collide>
        <kinematic>0</kinematic>
      </link>
      <joint name='r_leg_hpz' type='revolute'>
        <child>r_uglut</child>
        <parent>pelvis</parent>
        <axis>
          <xyz>0 0 1</xyz>
          <limit>
            <lower>-0.786794</lower>
            <upper>0.174358</upper>
            <effort>275</effort>
            <velocity>12</velocity>
          </limit>
          <dynamics>
            <damping>0.1</damping>
            <friction>0</friction>
            <spring_reference>0</spring_reference>
            <spring_stiffness>0</spring_stiffness>
          </dynamics>
          <use_parent_model_frame>1</use_parent_model_frame>
        </axis>
        <physics>
          <ode>
            <implicit_spring_damper>1</implicit_spring_damper>
            <cfm_damping>1</cfm_damping>
            <limit>
              <cfm>0</cfm>
              <erp>0.2</erp>
            </limit>
          </ode>
        </physics>
      </joint>
      <link name='r_lglut'>
        <pose frame=''>0 -0.089 0 0 -0 0</pose>
        <inertial>
          <pose frame=''>0.0133341 -0.0170484 -0.0312052 0 -0 0</pose>
          <mass>0.898</mass>
          <inertia>
            <ixx>0.000691326</ixx>
            <ixy>2.24344e-05</ixy>
            <ixz>2.50508e-06</ixz>
            <iyy>0.00126856</iyy>
            <iyz>-0.000137862</iyz>
            <izz>0.00106487</izz>
          </inertia>
        </inertial>
        <collision name='r_lglut_collision'>
          <pose frame=''>0.015 -0.026 -0.028 0 -0 0</pose>
          <geometry>
            <box>
              <size>0.125 0.05 0.08</size>
            </box>
          </geometry>
          <surface>
            <contact>
              <ode/>
            </contact>
            <friction>
              <ode>
                <mu>0.9</mu>
                <mu2>0.9</mu2>
              </ode>
            </friction>
            <bounce/>
          </surface>
          <max_contacts>10</max_contacts>
        </collision>
        <collision name='r_lglut_collision_r_lglut_1'>
          <pose frame=''>0.05 -0.027488 -0.067 1.5708 -0 0</pose>
          <geometry>
            <cylinder>
              <length>0.060306</length>
              <radius>0.0200969</radius>
            </cylinder>
          </geometry>
          <surface>
            <contact>
              <ode/>
            </contact>
            <friction>
              <ode>
                <mu>0.9</mu>
                <mu2>0.9</mu2>
              </ode>
            </friction>
            <bounce/>
          </surface>
          <max_contacts>10</max_contacts>
        </collision>
        <collision name='r_lglut_collision_r_lglut_2'>
          <pose frame=''>0.0105 0 0 -2.65359e-06 1.57079 -2.65359e-06</pose>
          <geometry>
            <cylinder>
              <length>0.142</length>
              <radius>0.02</radius>
            </cylinder>
          </geometry>
          <surface>
            <contact>
              <ode/>
            </contact>
            <friction>
              <ode>
                <mu>0.9</mu>
                <mu2>0.9</mu2>
              </ode>
            </friction>
            <bounce/>
          </surface>
          <max_contacts>10</max_contacts>
        </collision>
        <collision name='r_lglut_collision_r_lglut_3'>
          <pose frame=''>0.01 -0.02 0.01 0 -0 0</pose>
          <geometry>
            <box>
              <size>0.0975 0.069 0.103</size>
            </box>
          </geometry>
          <surface>
            <contact>
              <ode/>
            </contact>
            <friction>
              <ode>
                <mu>0.9</mu>
                <mu2>0.9</mu2>
              </ode>
            </friction>
            <bounce/>
          </surface>
          <max_contacts>10</max_contacts>
        </collision>
        <visual name='r_lglut_visual'>
          <pose frame=''>0 0 0 0 -0 0</pose>
          <geometry>
            <mesh>
              <scale>1 1 1</scale>
              <uri>model://atlas_description/meshes_unplugged/r_lglut.dae</uri>
            </mesh>
          </geometry>
        </visual>
        <gravity>1</gravity>
        <velocity_decay/>
        <self_collide>0</self_collide>
        <kinematic>0</kinematic>
      </link>
      <joint name='r_leg_hpx' type='revolute'>
        <child>r_lglut</child>
        <parent>r_uglut</parent>
        <axis>
          <xyz>1 0 0</xyz>
          <limit>
            <lower>-0.523599</lower>
            <upper>0.523599</upper>
            <effort>530</effort>
            <velocity>12</velocity>
          </limit>
          <dynamics>
            <damping>0.1</damping>
            <friction>0</friction>
            <spring_reference>0</spring_reference>
            <spring_stiffness>0</spring_stiffness>
          </dynamics>
          <use_parent_model_frame>1</use_parent_model_frame>
        </axis>
        <physics>
          <ode>
            <implicit_spring_damper>1</implicit_spring_damper>
            <cfm_damping>1</cfm_damping>
            <limit>
              <cfm>0</cfm>
              <erp>0.2</erp>
            </limit>
          </ode>
        </physics>
      </joint>
      <link name='r_uleg'>
        <pose frame=''>0.05 -0.1115 -0.066 0 -0 0</pose>
        <inertial>
          <pose frame=''>0 0 -0.21 0 -0 0</pose>
          <mass>8.204</mass>
          <inertia>
            <ixx>0.09</ixx>
            <ixy>0</ixy>
            <ixz>0</ixz>
            <iyy>0.09</iyy>
            <iyz>0</iyz>
            <izz>0.02</izz>
          </inertia>
        </inertial>
        <collision name='r_uleg_collision'>
          <pose frame=''>-0.0199 -0.00585 -0.122 0 -0 0</pose>
          <geometry>
            <cylinder>
              <length>0.15</length>
              <radius>0.09</radius>
            </cylinder>
          </geometry>
          <surface>
            <contact>
              <ode/>
            </contact>
            <friction>
              <ode>
                <mu>0.9</mu>
                <mu2>0.9</mu2>
              </ode>
            </friction>
            <bounce/>
          </surface>
          <max_contacts>10</max_contacts>
        </collision>
        <collision name='r_uleg_collision_r_uleg_1'>
          <pose frame=''>-0.032 0.005 -0.224 0 -0.3 0</pose>
          <geometry>
            <cylinder>
              <length>0.15</length>
              <radius>0.07</radius>
            </cylinder>
          </geometry>
          <surface>
            <contact>
              <ode/>
            </contact>
            <friction>
              <ode>
                <mu>0.9</mu>
                <mu2>0.9</mu2>
              </ode>
            </friction>
            <bounce/>
          </surface>
          <max_contacts>10</max_contacts>
        </collision>
        <collision name='r_uleg_collision_r_uleg_2'>
          <pose frame=''>0.003 -0.015 -0.254 0.15 0.13 -6.99794e-18</pose>
          <geometry>
            <cylinder>
              <length>0.15</length>
              <radius>0.05</radius>
            </cylinder>
          </geometry>
          <surface>
            <contact>
              <ode/>
            </contact>
            <friction>
              <ode>
                <mu>0.9</mu>
                <mu2>0.9</mu2>
              </ode>
            </friction>
            <bounce/>
          </surface>
          <max_contacts>10</max_contacts>
        </collision>
        <collision name='r_uleg_collision_r_uleg_3'>
          <pose frame=''>-0.007 0.053 -0.052 0 -0 0</pose>
          <geometry>
            <box>
              <size>0.07 0.038 0.15</size>
            </box>
          </geometry>
          <surface>
            <contact>
              <ode/>
            </contact>
            <friction>
              <ode>
                <mu>0.9</mu>
                <mu2>0.9</mu2>
              </ode>
            </friction>
            <bounce/>
          </surface>
          <max_contacts>10</max_contacts>
        </collision>
        <collision name='r_uleg_collision_r_uleg_4'>
          <pose frame=''>-0.017 -0.0595 -0.049 0 -0 0</pose>
          <geometry>
            <box>
              <size>0.07 0.038 0.14</size>
            </box>
          </geometry>
          <surface>
            <contact>
              <ode/>
            </contact>
            <friction>
              <ode>
                <mu>0.9</mu>
                <mu2>0.9</mu2>
              </ode>
            </friction>
            <bounce/>
          </surface>
          <max_contacts>10</max_contacts>
        </collision>
        <visual name='r_uleg_visual'>
          <pose frame=''>0 0 0 0 -0 0</pose>
          <geometry>
            <mesh>
              <scale>1 1 1</scale>
              <uri>model://atlas_description/meshes_unplugged/r_uleg.dae</uri>
            </mesh>
          </geometry>
        </visual>
        <gravity>1</gravity>
        <velocity_decay/>
        <self_collide>0</self_collide>
        <kinematic>0</kinematic>
      </link>
      <joint name='r_leg_hpy' type='revolute'>
        <child>r_uleg</child>
        <parent>r_lglut</parent>
        <axis>
          <xyz>0 1 0</xyz>
          <limit>
            <lower>-1.61234</lower>
            <upper>0.65764</upper>
            <effort>840</effort>
            <velocity>12</velocity>
          </limit>
          <dynamics>
            <damping>0.1</damping>
            <friction>0</friction>
            <spring_reference>0</spring_reference>
            <spring_stiffness>0</spring_stiffness>
          </dynamics>
          <use_parent_model_frame>1</use_parent_model_frame>
        </axis>
        <physics>
          <ode>
            <implicit_spring_damper>1</implicit_spring_damper>
            <cfm_damping>1</cfm_damping>
            <limit>
              <cfm>0</cfm>
              <erp>0.2</erp>
            </limit>
          </ode>
        </physics>
      </joint>
      <link name='r_lleg'>
        <pose frame=''>0 -0.1115 -0.44 0 -0 0</pose>
        <inertial>
          <pose frame=''>0.001 0 -0.187 0 -0 0</pose>
          <mass>4.515</mass>
          <inertia>
            <ixx>0.077</ixx>
            <ixy>-0</ixy>
            <ixz>-0.003</ixz>
            <iyy>0.076</iyy>
            <iyz>-0</iyz>
            <izz>0.01</izz>
          </inertia>
        </inertial>
        <collision name='r_lleg_collision'>
          <pose frame=''>0.02 -0.00295 -0.182 0 0.1 0</pose>
          <geometry>
            <cylinder>
              <length>0.4</length>
              <radius>0.07</radius>
            </cylinder>
          </geometry>
          <surface>
            <contact>
              <ode/>
            </contact>
            <friction>
              <ode>
                <mu>0.9</mu>
                <mu2>0.9</mu2>
              </ode>
            </friction>
            <bounce/>
          </surface>
          <max_contacts>10</max_contacts>
        </collision>
        <visual name='r_lleg_visual'>
          <pose frame=''>0 0 0 0 -0 0</pose>
          <geometry>
            <mesh>
              <scale>1 1 1</scale>
              <uri>model://atlas_description/meshes_unplugged/r_lleg.dae</uri>
            </mesh>
          </geometry>
        </visual>
        <gravity>1</gravity>
        <velocity_decay/>
        <self_collide>0</self_collide>
        <kinematic>0</kinematic>
      </link>
      <joint name='r_leg_kny' type='revolute'>
        <child>r_lleg</child>
        <parent>r_uleg</parent>
        <axis>
          <xyz>0 1 0</xyz>
          <limit>
            <lower>0</lower>
            <upper>2.35637</upper>
            <effort>890</effort>
            <velocity>12</velocity>
          </limit>
          <dynamics>
            <damping>0.1</damping>
            <friction>0</friction>
            <spring_reference>0</spring_reference>
            <spring_stiffness>0</spring_stiffness>
          </dynamics>
          <use_parent_model_frame>1</use_parent_model_frame>
        </axis>
        <physics>
          <ode>
            <implicit_spring_damper>1</implicit_spring_damper>
            <cfm_damping>1</cfm_damping>
            <limit>
              <cfm>0</cfm>
              <erp>0.2</erp>
            </limit>
          </ode>
        </physics>
      </joint>
      <link name='r_talus'>
        <pose frame=''>0 -0.1115 -0.862 0 -0 0</pose>
        <inertial>
          <pose frame=''>0 0 0 0 -0 0</pose>
          <mass>0.125</mass>
          <inertia>
            <ixx>1.01674e-05</ixx>
            <ixy>0</ixy>
            <ixz>0</ixz>
            <iyy>8.42775e-06</iyy>
            <iyz>0</iyz>
            <izz>1.30101e-05</izz>
          </inertia>
        </inertial>
        <collision name='r_talus_collision'>
          <pose frame=''>0 0 0 -2.65359e-06 1.57079 -2.65359e-06</pose>
          <geometry>
            <cylinder>
              <length>0.029542</length>
              <radius>0.010181</radius>
            </cylinder>
          </geometry>
          <surface>
            <contact>
              <ode/>
            </contact>
            <friction>
              <ode>
                <mu>0.9</mu>
                <mu2>0.9</mu2>
              </ode>
            </friction>
            <bounce/>
          </surface>
          <max_contacts>10</max_contacts>
        </collision>
        <collision name='r_talus_collision_r_talus_1'>
          <pose frame=''>0 0 0 1.5708 -0 0</pose>
          <geometry>
            <cylinder>
              <length>0.010059</length>
              <radius>0.010348</radius>
            </cylinder>
          </geometry>
          <surface>
            <contact>
              <ode/>
            </contact>
            <friction>
              <ode>
                <mu>0.9</mu>
                <mu2>0.9</mu2>
              </ode>
            </friction>
            <bounce/>
          </surface>
          <max_contacts>10</max_contacts>
        </collision>
        <visual name='r_talus_visual'>
          <pose frame=''>0 0 0 0 -0 0</pose>
          <geometry>
            <mesh>
              <scale>1 1 1</scale>
              <uri>model://atlas_description/meshes_unplugged/r_talus.dae</uri>
            </mesh>
          </geometry>
        </visual>
        <gravity>1</gravity>
        <velocity_decay/>
        <self_collide>0</self_collide>
        <kinematic>0</kinematic>
      </link>
      <joint name='r_leg_aky' type='revolute'>
        <child>r_talus</child>
        <parent>r_lleg</parent>
        <axis>
          <xyz>0 1 0</xyz>
          <limit>
            <lower>-1</lower>
            <upper>0.7</upper>
            <effort>740</effort>
            <velocity>12</velocity>
          </limit>
          <dynamics>
            <damping>0.1</damping>
            <friction>0</friction>
            <spring_reference>0</spring_reference>
            <spring_stiffness>0</spring_stiffness>
          </dynamics>
          <use_parent_model_frame>1</use_parent_model_frame>
        </axis>
        <physics>
          <ode>
            <implicit_spring_damper>1</implicit_spring_damper>
            <cfm_damping>1</cfm_damping>
            <limit>
              <cfm>0</cfm>
              <erp>0.2</erp>
            </limit>
          </ode>
        </physics>
      </joint>
      <link name='r_foot'>
        <pose frame=''>0 -0.1115 -0.862 0 -0 0</pose>
        <inertial>
          <pose frame=''>0.027 0 -0.067 0 -0 0</pose>
          <mass>2.41</mass>
          <inertia>
            <ixx>0.002</ixx>
            <ixy>0</ixy>
            <ixz>0</ixz>
            <iyy>0.007</iyy>
            <iyz>0</iyz>
            <izz>0.008</izz>
          </inertia>
        </inertial>
        <collision name='r_foot_collision'>
          <pose frame=''>0.023 0 -0.049119 0 -0 0</pose>
          <geometry>
            <box>
              <size>0.227 0.133887 0.05</size>
            </box>
          </geometry>
          <surface>
            <contact>
              <ode>
                <kp>1e+06</kp>
                <kd>100</kd>
                <max_vel>1</max_vel>
                <min_depth>0</min_depth>
              </ode>
            </contact>
            <friction>
              <ode>
                <mu>1.5</mu>
                <mu2>1.5</mu2>
                <fdir1>1 0 0</fdir1>
              </ode>
            </friction>
            <bounce/>
          </surface>
          <surface>
            <contact>
              <ode/>
            </contact>
            <friction>
              <ode/>
            </friction>
          </surface>
          <max_contacts>10</max_contacts>
        </collision>
        <collision name='r_foot_collision_r_foot_1'>
          <pose frame=''>0.1225 0 -0.0641 0 -0 0</pose>
          <geometry>
            <box>
              <size>0.1 0.08 0.02</size>
            </box>
          </geometry>
          <surface>
            <contact>
              <ode>
                <kp>1e+06</kp>
                <kd>100</kd>
                <max_vel>1</max_vel>
                <min_depth>0</min_depth>
              </ode>
            </contact>
            <friction>
              <ode>
                <mu>1.5</mu>
                <mu2>1.5</mu2>
                <fdir1>1 0 0</fdir1>
              </ode>
            </friction>
            <bounce/>
          </surface>
          <surface>
            <contact>
              <ode/>
            </contact>
            <friction>
              <ode/>
            </friction>
          </surface>
          <max_contacts>10</max_contacts>
        </collision>
        <visual name='r_foot_visual'>
          <pose frame=''>0 0 0 0 -0 0</pose>
          <geometry>
            <mesh>
              <scale>1 1 1</scale>
              <uri>model://atlas_description/meshes_unplugged/r_foot.dae</uri>
            </mesh>
          </geometry>
        </visual>
        <velocity_decay/>
        <gravity>1</gravity>
        <velocity_decay/>
        <self_collide>0</self_collide>
        <sensor name='r_foot_contact_sensor' type='contact'>
          <update_rate>1000</update_rate>
          <always_on>1</always_on>
          <contact>
            <collision>r_foot_collision</collision>
            <topic>/r_foot_contact</topic>
          </contact>
        </sensor>
        <kinematic>0</kinematic>
      </link>
      <joint name='r_leg_akx' type='revolute'>
        <child>r_foot</child>
        <parent>r_talus</parent>
        <axis>
          <xyz>1 0 0</xyz>
          <limit>
            <lower>-0.8</lower>
            <upper>0.8</upper>
            <effort>360</effort>
            <velocity>12</velocity>
          </limit>
          <dynamics>
            <damping>0.1</damping>
            <friction>0</friction>
            <spring_reference>0</spring_reference>
            <spring_stiffness>0</spring_stiffness>
          </dynamics>
          <use_parent_model_frame>1</use_parent_model_frame>
        </axis>
        <physics>
          <provide_feedback>1</provide_feedback>
          <ode>
            <provide_feedback>1</provide_feedback>
            <implicit_spring_damper>1</implicit_spring_damper>
            <cfm_damping>1</cfm_damping>
            <limit>
              <cfm>0</cfm>
              <erp>0.2</erp>
            </limit>
          </ode>
        </physics>
      </joint>
      <pose frame=''>0 0 0.93 0 -0 0</pose>
      <plugin name='atlas_plugin' filename='libAtlasV4Plugin.so'/>
      <plugin name='joint_trajectory_plugin' filename='libgazebo_ros_joint_pose_trajectory.so'>
        <topicName>joint_trajectory</topicName>
        <updateRate>1000.0</updateRate>
      </plugin>
      <plugin name='gazebo_ros_p3d' filename='libgazebo_ros_p3d.so'>
        <bodyName>pelvis</bodyName>
        <topicName>/ground_truth_odom</topicName>
        <alwaysOn>true</alwaysOn>
        <updateRate>100.0</updateRate>
      </plugin>
      <plugin name='gazebo_ros_force' filename='libgazebo_ros_force.so'>
        <bodyName>pelvis</bodyName>
        <topicName>/atlas/apply_pelvis_force</topicName>
      </plugin>
      <static>0</static>
      <plugin name='multisense_plugin' filename='libMultiSenseSLPlugin.so'/>
    </model>
    <model name='unit_sphere_1'>
      <plugin filename="libball_throwing.so" name="ball_throwing">
      </plugin>
      <pose frame=''>4 0 0.5 0 -0 0</pose>
      <link name='link'>
        <inertial>
          <mass>1</mass>
          <inertia>
            <ixx>1</ixx>
            <ixy>0</ixy>
            <ixz>0</ixz>
            <iyy>1</iyy>
            <iyz>0</iyz>
            <izz>1</izz>
          </inertia>
        </inertial>
        <collision name='collision'>
          <geometry>
            <sphere>
              <radius>0.0929669</radius>
            </sphere>
          </geometry>
          <max_contacts>10</max_contacts>
          <surface>
            <contact>
              <ode/>
            </contact>
            <bounce/>
            <friction>
              <ode/>
            </friction>
          </surface>
        </collision>
        <visual name='visual'>
          <geometry>
            <sphere>
              <radius>0.0929669</radius>
            </sphere>
          </geometry>
          <material>
            <script>
              <uri>file://media/materials/scripts/gazebo.material</uri>
              <name>Gazebo/Grey</name>
            </script>
          </material>
        </visual>
        <self_collide>0</self_collide>
        <kinematic>0</kinematic>
        <gravity>1</gravity>
      </link>
    </model>
    <state world_name='default'>
      <sim_time>82 855000000</sim_time>
      <real_time>112 218873555</real_time>
      <wall_time>1511667822 887403991</wall_time>
      <model name='atlas'>
        <pose frame=''>0.042738 -0.013194 0.870281 -0.002814 0.002516 0.030182</pose>
        <link name='head'>
          <pose frame=''>0.286568 -0.003477 1.70323 -0.002846 -0.158303 0.030624</pose>
          <velocity>-0.22374 0.062158 0.080273 3.12195 -1.2899 3.12105</velocity>
          <acceleration>3.55881 -0.157172 -2.59235 0.020376 -0.644469 0.000329</acceleration>
          <wrench>5.05319 -0.223171 -3.6809 0 -0 0</wrench>
        </link>
        <link name='hokuyo_link'>
          <pose frame=''>0.228673 -0.005 1.7831 -0.036955 -0.158303 0.030624</pose>
          <velocity>-0.371573 0.064915 -0.02679 3.12352 -1.28994 3.1213</velocity>
          <acceleration>4.20451 -0.115432 -3.50664 -0.001261 0.009595 0.000778</acceleration>
          <wrench>0.242449 -0.006656 -0.202207 0 -0 0</wrench>
        </link>
        <link name='l_clav'>
          <pose frame=''>0.165506 0.218167 1.55895 0.003328 -0.001328 2.88137</pose>
          <velocity>-0.162676 0.055913 0.019511 -0.063623 -0.384228 0.072733</velocity>
          <acceleration>0.379588 -0.037401 -2.05935 -2.39302 -0.638327 1.94397</acceleration>
          <wrench>1.69524 -0.167034 -9.19704 0 -0 0</wrench>
        </link>
        <link name='l_foot'>
          <pose frame=''>0.00507 0.143568 0.074022 -0.000324 0.000515 0.250515</pose>
          <velocity>0.000292 -0.000301 0.001174 0.003856 0.004503 0.000154</velocity>
          <acceleration>-0.001178 0.00025 -0.054393 0.441934 0.394682 -0.000937</acceleration>
          <wrench>-0.002839 0.000601 -0.131088 0 -0 0</wrench>
        </link>
        <link name='l_hand'>
          <pose frame=''>0.330443 0.424442 0.739042 1.29077 -0.285967 1.05735</pose>
          <velocity>-0.02687 -0.1954 -0.024147 0.605148 0.422228 -2.0189</velocity>
          <acceleration>17.3167 -27.8709 2.09725 -0.046038 -0.071476 -0.020127</acceleration>
          <wrench>10.1112 -16.2738 1.22459 0 -0 0</wrench>
        </link>
        <link name='l_larm'>
          <pose frame=''>0.220466 0.392849 1.01603 1.27501 -0.291953 1.03585</pose>
          <velocity>-0.001567 -0.102388 -0.003521 -0.291254 0.104072 -0.112003</velocity>
          <acceleration>-3.55029 -5.8916 -3.79524 0.284243 -0.290651 0.140681</acceleration>
          <wrench>-11.5313 -19.1359 -12.3269 0 -0 0</wrench>
        </link>
        <link name='l_lfarm'>
          <pose frame=''>0.330443 0.424442 0.739042 1.84628 0.290333 -2.10022</pose>
          <velocity>-0.026887 -0.195372 -0.024161 0.432672 0.375885 -1.59399</velocity>
          <acceleration>12.702 -23.457 0.502633 1.68138 1.46269 0.371829</acceleration>
          <wrench>8.2309 -15.2002 0.325706 0 -0 0</wrench>
        </link>
        <link name='l_lglut'>
          <pose frame=''>0.04005 0.075763 0.870037 0.064984 0.002973 0.250116</pose>
          <velocity>0.068912 0.019554 -0.019668 0.053079 -0.213415 -0.02641</velocity>
          <acceleration>-5.69911 0.119455 -0.81442 -0.508686 -1.33304 1.32268</acceleration>
          <wrench>-5.1178 0.10727 -0.73135 0 -0 0</wrench>
        </link>
        <link name='l_lleg'>
          <pose frame=''>0.195758 0.167008 0.449745 0.072807 0.467462 0.282779</pose>
          <velocity>0.045701 0.011046 -0.022568 -0.032178 0.120681 -0.003931</velocity>
          <acceleration>-0.63988 -0.094031 0.236552 -2.64074 1.20099 -2.28429</acceleration>
          <wrench>-2.88906 -0.424549 1.06803 0 -0 0</wrench>
        </link>
        <link name='l_scap'>
          <pose frame=''>0.193284 0.323759 1.31359 1.2678 -0.00133 2.88137</pose>
          <velocity>-0.076036 0.042294 0.023458 -0.485285 -0.271866 0.073445</velocity>
          <acceleration>0.042211 -0.292744 -2.26672 -0.328054 0.957823 2.12222</acceleration>
          <wrench>0.16458 -1.14141 -8.83792 0 -0 0</wrench>
        </link>
        <link name='l_talus'>
          <pose frame=''>0.005071 0.143567 0.074022 0.064984 0.000522 0.250512</pose>
          <velocity>0.000233 -0.000294 0.001166 -0.001956 0.002355 8.6e-05</velocity>
          <acceleration>-0.037867 0.000812 -0.069183 -1.684 -1.07202 1.97331</acceleration>
          <wrench>-0.004733 0.000101 -0.008648 0 -0 0</wrench>
        </link>
        <link name='l_uarm'>
          <pose frame=''>0.203476 0.362985 1.13033 1.65305 -0.291955 1.03585</pose>
          <velocity>-0.029088 -0.045896 0.007177 -0.462598 -0.185062 -0.213063</velocity>
          <acceleration>-1.57344 -2.58045 -2.68827 0.440178 -0.542952 -3.04415</acceleration>
          <wrench>-6.9011 -11.3179 -11.7908 0 -0 0</wrench>
        </link>
        <link name='l_ufarm'>
          <pose frame=''>0.330443 0.424442 0.739042 1.86817 0.290334 -2.10022</pose>
          <velocity>-0.026921 -0.19536 -0.02418 0.359996 0.251399 -1.63703</velocity>
          <acceleration>6.64716 -17.3305 -1.2552 -0.760704 -0.216418 -0.08913</acceleration>
          <wrench>16.4836 -42.9761 -3.11264 0 -0 0</wrench>
        </link>
        <link name='l_uglut'>
          <pose frame=''>0.040052 0.075764 0.870033 -0.002187 0.003012 0.25012</pose>
          <velocity>0.068894 0.019548 -0.019629 -0.04659 -0.239239 -0.026184</velocity>
          <acceleration>-5.60982 0.22455 -0.743775 0.861345 0.217845 0.577333</acceleration>
          <wrench>-10.9896 0.439893 -1.45705 0 -0 0</wrench>
        </link>
        <link name='l_uleg'>
          <pose frame=''>0.081687 0.113998 0.805489 0.07274 -0.465672 0.217215</pose>
          <velocity>0.08373 0.021865 -0.00876 -0.028859 0.107619 -0.004845</velocity>
          <acceleration>-3.31627 -0.245717 0.134312 -0.695563 0.247219 2.98988</acceleration>
          <wrench>-27.2067 -2.01586 1.10189 0 -0 0</wrench>
        </link>
        <link name='ltorso'>
          <pose frame=''>0.030246 -0.01357 0.870311 -0.002842 0.002553 0.030169</pose>
          <velocity>0.073031 0.019113 -0.017798 -0.046679 -0.240349 -0.025141</velocity>
          <acceleration>-4.50173 0.11048 -0.647578 0.229997 -0.360759 0.157517</acceleration>
          <wrench>-10.2189 0.250789 -1.47 0 -0 0</wrench>
        </link>
        <link name='mtorso'>
          <pose frame=''>0.030646 -0.013096 1.0323 -0.003001 0.00223 0.03017</pose>
          <velocity>0.034112 0.026684 -0.017589 -0.040571 -0.383838 -0.02467</velocity>
          <acceleration>-3.65947 0.055142 -0.651363 -1.366 1.21443 0.002609</acceleration>
          <wrench>-2.92391 0.044058 -0.520439 0 -0 0</wrench>
        </link>
        <link name='pelvis'>
          <pose frame=''>0.042738 -0.013194 0.870281 -0.002814 0.002516 0.030182</pose>
          <velocity>0.073054 0.019686 -0.014857 -0.046189 -0.23949 0.047488</velocity>
          <acceleration>-4.7867 0.33946 -0.844345 0.008308 0.058034 0.307907</acceleration>
          <wrench>-45.9954 3.26187 -8.11331 0 -0 0</wrench>
        </link>
        <link name='r_clav'>
          <pose frame=''>0.179119 -0.232826 1.56022 -0.002046 0.002942 0.321756</pose>
          <velocity>-0.174262 0.055662 0.053584 -0.064237 -0.384773 -0.144026</velocity>
          <acceleration>0.984344 -0.016321 -2.5319 -0.449882 0.22399 2.81793</acceleration>
          <wrench>4.39608 -0.07289 -11.3074 0 -0 0</wrench>
        </link>
        <link name='r_foot'>
          <pose frame=''>-0.022853 -0.178701 0.074033 -0.000313 -2.6e-05 -0.678517</pose>
          <velocity>0.000343 -0.000115 0.001226 0.00175 0.004901 1.9e-05</velocity>
          <acceleration>-0.00096 9.9e-05 -0.035796 -0.185467 -1.07652 -3.1411</acceleration>
          <wrench>-0.002313 0.000238 -0.086268 0 -0 0</wrench>
        </link>
        <link name='r_hand'>
          <pose frame=''>0.353449 -0.414794 0.73849 1.28463 0.272426 2.19434</pose>
          <velocity>0.158073 0.106194 0.140319 3.04566 -0.150823 1.94717</velocity>
          <acceleration>17.714 17.64 3.65293 0.02695 -0.049446 0.017247</acceleration>
          <wrench>10.3432 10.3 2.13295 0 -0 0</wrench>
        </link>
        <link name='r_larm'>
          <pose frame=''>0.242215 -0.39921 1.01634 1.26309 0.269712 2.18464</pose>
          <velocity>-0.00094 0.047148 0.080073 0.218555 -0.572709 -0.012216</velocity>
          <acceleration>-0.898433 0.174897 -3.00573 -0.354652 1.11623 0.429289</acceleration>
          <wrench>-2.91811 0.568066 -9.76261 0 -0 0</wrench>
        </link>
        <link name='r_lfarm'>
          <pose frame=''>0.353449 -0.414794 0.73849 1.28147 0.269055 2.18251</pose>
          <velocity>0.158011 0.106503 0.140292 -0.638108 -0.457963 1.89918</velocity>
          <acceleration>14.6138 14.7129 2.64537 -1.87569 1.21312 0.301455</acceleration>
          <wrench>9.46974 9.53394 1.7142 0 -0 0</wrench>
        </link>
        <link name='r_lglut'>
          <pose frame=''>0.045425 -0.102153 0.870533 -0.099903 6.1e-05 -0.676518</pose>
          <velocity>0.077204 0.019796 -0.010152 -0.196598 -0.117727 0.014473</velocity>
          <acceleration>-4.20571 0.43468 -0.962548 -0.392001 -1.48922 1.28092</acceleration>
          <wrench>-3.77673 0.390342 -0.864368 0 -0 0</wrench>
        </link>
        <link name='r_lleg'>
          <pose frame=''>0.142301 -0.262572 0.453203 -0.110527 0.441686 -0.723917</pose>
          <velocity>0.031637 0.011189 -0.009824 -0.034915 0.084954 -0.011523</velocity>
          <acceleration>-0.115328 -0.114078 -0.032043 2.8781 -0.056696 -0.904523</acceleration>
          <wrench>-0.520706 -0.51506 -0.144674 0 -0 0</wrench>
        </link>
        <link name='r_scap'>
          <pose frame=''>0.213381 -0.337885 1.31545 1.28895 0.002941 0.321756</pose>
          <velocity>-0.095177 0.035027 0.073508 0.053101 -0.34557 -0.144435</velocity>
          <acceleration>0.905832 0.648177 -2.96466 -2.38754 -1.41633 0.117441</acceleration>
          <wrench>3.53184 2.52724 -11.5592 0 -0 0</wrench>
        </link>
        <link name='r_talus'>
          <pose frame=''>-0.022855 -0.178699 0.074029 -0.099884 0.000197 -0.676538</pose>
          <velocity>0.000387 -0.000144 0.001276 -0.060059 0.053676 -0.007481</velocity>
          <acceleration>-0.017192 0.010154 -0.04534 2.53547 -1.20632 0.836101</acceleration>
          <wrench>-0.002149 0.001269 -0.005667 0 -0 0</wrench>
        </link>
        <link name='r_uarm'>
          <pose frame=''>0.224455 -0.372819 1.13138 1.65369 0.269713 2.18464</pose>
          <velocity>-0.036603 0.043221 0.075474 0.048548 -0.331516 -0.093735</velocity>
          <acceleration>0.037319 0.387424 -2.95275 -0.537098 -1.11965 -2.01572</acceleration>
          <wrench>0.163679 1.69924 -12.9508 0 -0 0</wrench>
        </link>
        <link name='r_ufarm'>
          <pose frame=''>0.353448 -0.414794 0.73849 1.26252 0.269056 2.18251</pose>
          <velocity>0.157969 0.106583 0.140301 -0.606609 -0.502928 1.9143</velocity>
          <acceleration>9.38589 9.72741 0.481289 0.872213 -0.190125 -0.316472</acceleration>
          <wrench>23.2751 24.122 1.1935 0 -0 0</wrench>
        </link>
        <link name='r_uglut'>
          <pose frame=''>0.045425 -0.102153 0.870532 -0.003775 8.7e-05 -0.676512</pose>
          <velocity>0.077222 0.019821 -0.010121 -0.046247 -0.239606 0.014262</velocity>
          <acceleration>-4.22923 0.310935 -0.878814 -2.91386 -0.838262 -1.7186</acceleration>
          <wrench>-8.28506 0.609123 -1.7216 0 -0 0</wrench>
        </link>
        <link name='r_uleg'>
          <pose frame=''>0.066272 -0.156042 0.807105 -0.112124 -0.470763 -0.625486</pose>
          <velocity>0.085477 0.00759 0.002832 0.014347 0.146288 -0.019413</velocity>
          <acceleration>-1.9707 0.351346 -0.272081 2.24268 1.19924 0.155166</acceleration>
          <wrench>-16.1676 2.88244 -2.23215 0 -0 0</wrench>
        </link>
        <link name='utorso'>
          <pose frame=''>0.030753 -0.012945 1.0823 -0.00281 0.00223 0.03017</pose>
          <velocity>0.014919 0.028753 -0.017535 -0.063943 -0.384544 -0.024617</velocity>
          <acceleration>-0.092938 -0.249523 -0.133129 0.023051 0.220415 -0.01306</acceleration>
          <wrench>-7.86339 -21.1119 -11.2639 0 -0 0</wrench>
        </link>
      </model>
      <model name='ground_plane'>
        <pose frame=''>0 0 0 0 -0 0</pose>
        <link name='link'>
          <pose frame=''>0 0 0 0 -0 0</pose>
          <velocity>0 0 0 0 -0 0</velocity>
          <acceleration>0 0 0 0 -0 0</acceleration>
          <wrench>0 0 0 0 -0 0</wrench>
        </link>
      </model>
      <model name='unit_sphere_1'>
        <pose frame=''>4 0 0.092967 0 -0 0</pose>
        <link name='link'>
          <pose frame=''>4 0 0.092967 0 -0 0</pose>
          <velocity>0 0 0 0 -0 0</velocity>
          <acceleration>0 0 0 0 -0 0</acceleration>
          <wrench>0 0 0 0 -0 0</wrench>
        </link>
      </model>
      <iterations>0</iterations>
    </state>
  </world>
</sdf>
